Workbook

Sheet Simple 10Y Table
A1: ONE SIMPLE TABLE – 10-year cost at MEDIUM use (30 km/day). Other usage levels on '10-Year Total' sheet.
A2: Scooter | B2: Type | C2: Weight (kg) | D2: Within 85–95 kg? | E2: Purchase Cost | F2: Fuel/Electricity 10Y | G2: Maintenance 10Y | H2: Insurance 10Y (yrs 2–10) | I2: Major Repairs/Battery | J2: TOTAL 10Y (best case) | K2: TOTAL 10Y (conservative) | L2: Cost per km (conservative) | M2: Thoothukudi dealer
A3: =Shortlist!B2 | B3: =Shortlist!D2 | C3: =Shortlist!E2 | D3: =Shortlist!F2 | E3: ='10-Year Total'!C3 | F3: ='10-Year Total'!J3 | G3: ='10-Year Total'!K3 | H3: ='10-Year Total'!L3 | I3: ='10-Year Total'!M3 | J3: ='10-Year Total'!N3 | K3: ='10-Year Total'!O3 | L3: =K3/(Inputs!$B$7*Inputs!$B$9*10) | M3: =Shortlist!V2
A4: =Shortlist!B3 | B4: =Shortlist!D3 | C4: =Shortlist!E3 | D4: =Shortlist!F3 | E4: ='10-Year Total'!C4 | F4: ='10-Year Total'!J4 | G4: ='10-Year Total'!K4 | H4: ='10-Year Total'!L4 | I4: ='10-Year Total'!M4 | J4: ='10-Year Total'!N4 | K4: ='10-Year Total'!O4 | L4: =K4/(Inputs!$B$7*Inputs!$B$9*10) | M4: =Shortlist!V3
A5: =Shortlist!B4 | B5: =Shortlist!D4 | C5: =Shortlist!E4 | D5: =Shortlist!F4 | E5: ='10-Year Total'!C5 | F5: ='10-Year Total'!J5 | G5: ='10-Year Total'!K5 | H5: ='10-Year Total'!L5 | I5: ='10-Year Total'!M5 | J5: ='10-Year Total'!N5 | K5: ='10-Year Total'!O5 | L5: =K5/(Inputs!$B$7*Inputs!$B$9*10) | M5: =Shortlist!V4
A6: =Shortlist!B5 | B6: =Shortlist!D5 | C6: =Shortlist!E5 | D6: =Shortlist!F5 | E6: ='10-Year Total'!C6 | F6: ='10-Year Total'!J6 | G6: ='10-Year Total'!K6 | H6: ='10-Year Total'!L6 | I6: ='10-Year Total'!M6 | J6: ='10-Year Total'!N6 | K6: ='10-Year Total'!O6 | L6: =K6/(Inputs!$B$7*Inputs!$B$9*10) | M6: =Shortlist!V5
A7: =Shortlist!B6 | B7: =Shortlist!D6 | C7: =Shortlist!E6 | D7: =Shortlist!F6 | E7: ='10-Year Total'!C7 | F7: ='10-Year Total'!J7 | G7: ='10-Year Total'!K7 | H7: ='10-Year Total'!L7 | I7: ='10-Year Total'!M7 | J7: ='10-Year Total'!N7 | K7: ='10-Year Total'!O7 | L7: =K7/(Inputs!$B$7*Inputs!$B$9*10) | M7: =Shortlist!V6
A8: =Shortlist!B7 | B8: =Shortlist!D7 | C8: =Shortlist!E7 | D8: =Shortlist!F7 | E8: ='10-Year Total'!C8 | F8: ='10-Year Total'!J8 | G8: ='10-Year Total'!K8 | H8: ='10-Year Total'!L8 | I8: ='10-Year Total'!M8 | J8: ='10-Year Total'!N8 | K8: ='10-Year Total'!O8 | L8: =K8/(Inputs!$B$7*Inputs!$B$9*10) | M8: =Shortlist!V7
A9: =Shortlist!B8 | B9: =Shortlist!D8 | C9: =Shortlist!E8 | D9: =Shortlist!F8 | E9: ='10-Year Total'!C9 | F9: ='10-Year Total'!J9 | G9: ='10-Year Total'!K9 | H9: ='10-Year Total'!L9 | I9: ='10-Year Total'!M9 | J9: ='10-Year Total'!N9 | K9: ='10-Year Total'!O9 | L9: =K9/(Inputs!$B$7*Inputs!$B$9*10) | M9: =Shortlist!V8
A10: =Shortlist!B9 | B10: =Shortlist!D9 | C10: =Shortlist!E9 | D10: =Shortlist!F9 | E10: ='10-Year Total'!C10 | F10: ='10-Year Total'!J10 | G10: ='10-Year Total'!K10 | H10: ='10-Year Total'!L10 | I10: ='10-Year Total'!M10 | J10: ='10-Year Total'!N10 | K10: ='10-Year Total'!O10 | L10: =K10/(Inputs!$B$7*Inputs!$B$9*10) | M10: =Shortlist!V9
A11: =Shortlist!B10 | B11: =Shortlist!D10 | C11: =Shortlist!E10 | D11: =Shortlist!F10 | E11: ='10-Year Total'!C11 | F11: ='10-Year Total'!J11 | G11: ='10-Year Total'!K11 | H11: ='10-Year Total'!L11 | I11: ='10-Year Total'!M11 | J11: ='10-Year Total'!N11 | K11: ='10-Year Total'!O11 | L11: =K11/(Inputs!$B$7*Inputs!$B$9*10) | M11: =Shortlist!V10
A12: =Shortlist!B11 | B12: =Shortlist!D11 | C12: =Shortlist!E11 | D12: =Shortlist!F11 | E12: ='10-Year Total'!C12 | F12: ='10-Year Total'!J12 | G12: ='10-Year Total'!K12 | H12: ='10-Year Total'!L12 | I12: ='10-Year Total'!M12 | J12: ='10-Year Total'!N12 | K12: ='10-Year Total'!O12 | L12: =K12/(Inputs!$B$7*Inputs!$B$9*10) | M12: =Shortlist!V11
A14: Green = cheaper, red = dearer. Prices checked 5 Oct 2026. Estimates are clearly labelled on each sheet. Change inputs on the 'Inputs' sheet.

Sheet Inputs
A1: INPUTS & ASSUMPTIONS — change the yellow cells; every sheet updates
A3: Input | B3: Value | C3: Source / note
A4: Petrol price, Thoothukudi (₹/litre) | B4: 101.45 | C4: Shriram Finance / GoldPriceIndia – 17 Jul 2026 (latest dated figure found). Change to today's pump price.
A5: Electricity rate for charging (₹/unit) | B5: 7 | C5: ESTIMATE. TN domestic slabs ₹4.95–₹12.15/unit, no 2026 hike (TheDiscomBill, Jul 2026). Use 10 if your bill is in a high slab.
A6: Low use (km/day) | B6: 20 | C6: Your scenario
A7: Medium use (km/day) | B7: 30 | C7: Your scenario
A8: High use (km/day) | B8: 50 | C8: Your scenario
A9: Days per year | B9: 365
A10: Days per month | B10: 30
A11: Battery replacement price today (₹ per kWh) | B11: 20000 | C11: ESTIMATE from 2026 quotes: iQube 2.2 kWh ₹45–50k, Chetak 2.5 kWh ₹55–60k (EVFY 2026). May fall in future.
A12: Own-damage insurance rate (% of IDV per year) | B12: 0.0176 | C12: ESTIMATE (legacy IRDAI tariff for ≤150cc, Zone B). Actual varies by insurer.
A13: GST on insurance | B13: 0.18 | C13: Statutory
A14: Third-party premium – petrol 75–150cc (₹/yr, before GST) | B14: 714 | C14: IRDAI tariff (last notified). Prepaid for 5 years at purchase.
A15: Third-party premium – EV ≤3 kW (₹/yr, before GST) | B15: 457 | C15: IRDAI tariff (last notified). Prepaid for 5 years at purchase.
A16: Third-party premium – EV 3–7 kW (₹/yr, before GST) | B16: 607 | C16: IRDAI tariff (last notified).
A17: Your Hero Honda Pleasure kerb weight (kg) | B17: 104 | C17: BikeWale Pleasure 2005–2015 spec
A18: Target weight – minimum (kg) | B18: 85 | C18: Your requirement
A19: Target weight – maximum (kg) | B19: 95 | C19: Your requirement
A22: Insurance model (estimate): IDV falls with age; No-Claim Bonus (NCB) cuts own-damage premium if you make no claim
A23: Year | B23: IDV as % of ex-showroom | C23: NCB discount | D23: Third-party paid this year?
A24: 1 | B24: 0.95 | C24: 0 | D24: Prepaid at purchase (5-yr TP)
A25: 2 | B25: 0.85 | C25: 0.2 | D25: Prepaid at purchase (5-yr TP)
A26: 3 | B26: 0.8 | C26: 0.25 | D26: Prepaid at purchase (5-yr TP)
A27: 4 | B27: 0.7 | C27: 0.35 | D27: Prepaid at purchase (5-yr TP)
A28: 5 | B28: 0.6 | C28: 0.45 | D28: Prepaid at purchase (5-yr TP)
A29: 6 | B29: 0.5 | C29: 0.5 | D29: Yes – yearly
A30: 7 | B30: 0.45 | C30: 0.5 | D30: Yes – yearly
A31: 8 | B31: 0.4 | C31: 0.5 | D31: Yes – yearly
A32: 9 | B32: 0.35 | C32: 0.5 | D32: Yes – yearly
A33: 10 | B33: 0.3 | C33: 0.5 | D33: Yes – yearly
A35: IDV = Insured Declared Value = what the insurer would pay if the scooter is stolen/destroyed. Standard IRDAI depreciation: 5% (new), 15/20/30/40/50% by age 1–5; after 5 yrs by agreement (assumed 55–70% here).
A37: Maintenance unit costs (ESTIMATES for Thoothukudi authorised workshops, 2026 prices)
A38: Item | B38: Applies to | C38: Cost each time (₹) | D38: Every … km | E38: …or every … years | F38: Note
A39: Periodic service + engine oil (petrol) | B39: Petrol | C39: 900 | D39: 3000 | F39: Labour ~₹450 + 0.8 L oil ~₹450
A40: Oil filter / strainer clean | B40: Petrol | C40: 150 | D40: 6000 | F40: Most 110–125cc scooters have a mesh strainer
A41: Air filter | B41: Petrol | C41: 350 | D41: 12000
A42: Spark plug | B42: Petrol | C42: 200 | D42: 10000
A43: CVT belt | B43: Petrol | C43: 1200 | D43: 20000 | F43: Drive belt for automatic gearbox
A44: CVT rollers / clutch shoes | B44: Petrol | C44: 800 | D44: 25000
A45: Brake shoes/pads (both) | B45: Both | C45: 500 | D45: 12000
...

Sheet Shortlist
A1: # | B1: Scooter | C1: Variant used for costing | D1: Type | E1: Kerb weight (kg) | F1: Within 85–95 kg? | G1: Weight vs your Pleasure (kg) | H1: Battery (kWh) / Engine (cc) | I1: Real-world range (km) / mileage (kmpl) | J1: Claimed range / mileage | K1: Top speed (km/h) | L1: Seat height (mm) | M1: Storage | N1: Charging time | O1: Fuel tank (L) | P1: Brakes | Q1: Tyres / wheels | R1: Warranty | S1: EV energy use (Wh/km, incl. charging loss) | T1: Peak power (kW) | U1: Battery pack for replacement (kWh) | V1: Thoothukudi dealer status | W1: Simple verdict
A2: 1 | B2: Honda QC1 | C2: Standard (only variant) | D2: EV | E2: 89.5 | F2: =IF(AND(E2>=Inputs!$B$18,E2<=Inputs!$B$19),"YES","No – "&TEXT(E2-Inputs!$B$19,"0.0")&" kg over") | G2: =E2-Inputs!$B$17 | H2: 1.5 | I2: 60 | J2: 80 km (claimed) | K2: 50 | L2: 705 | M2: 26 L | N2: 4 h 40 min (0–80%) | O2: — | P2: Drum/drum, CBS † | Q2: 12-inch front † | R2: Battery 3 yr/50,000 km † – confirm | S2: 28 | T2: 1.8 | U2: 1.5 | V2: Not confirmed in Thoothukudi | W2: Lightest real scooter; 50 km/h max; only if Pearl Honda sells & services it
A3: 2 | B3: Kinetic DX | C3: DX 2.6 kWh (Standard) | D3: EV | E3: 90 | F3: =IF(AND(E3>=Inputs!$B$18,E3<=Inputs!$B$19),"YES","No – "&TEXT(E3-Inputs!$B$19,"0.0")&" kg over") | G3: =E3-Inputs!$B$17 | H3: 2.6 | I3: 80 | J3: 102 km (claimed) | K3: 80 | L3: n/a | M3: Not confirmed | N3: 3 h (0–80%) | O3: — | P3: 220 mm disc front / 130 mm drum rear, CBS ✅ | Q3: 12-inch alloys ✅ | R3: Not confirmed | S3: 34 | T3: 4.7 | U3: 2.6 | V3: Not confirmed in Thoothukudi (no dealer in Thoothukudi or Tirunelveli) | W3: Best EV spec in your weight range, but NO local dealer = risky
A4: 3 | B4: Kinetic Green Zulu | C4: Standard (only variant) | D4: EV | E4: 93 | F4: =IF(AND(E4>=Inputs!$B$18,E4<=Inputs!$B$19),"YES","No – "&TEXT(E4-Inputs!$B$19,"0.0")&" kg over") | G4: =E4-Inputs!$B$17 | H4: 2.27 | I4: 75 | J4: 104 km (claimed) | K4: 60 | L4: n/a | M4: Front + under-seat | N4: 3 h (0–80%, 15A socket) | O4: — | P4: Not confirmed | Q4: Not confirmed | R4: Not confirmed | S4: 32 | T4: 2.1 | U4: 2.27 | V4: Not confirmed in Thoothukudi | W4: In range, but small brand with no local support
A5: 4 | B5: TVS Orbiter (closest alternative) | C5: V1 1.8 kWh | D5: EV | E5: 101 | F5: =IF(AND(E5>=Inputs!$B$18,E5<=Inputs!$B$19),"YES","No – "&TEXT(E5-Inputs!$B$19,"0.0")&" kg over") | G5: =E5-Inputs!$B$17 | H5: 1.8 | I5: 70 | J5: 86 km (claimed) | K5: 68 | L5: 760 | M5: 34 L | N5: Not confirmed | O5: — | P5: Combined braking † | Q5: 14-inch front † | R5: 3 yr † – confirm | S5: 29 | U5: 1.8 | V5: TVS dealers listed in city (Orbiter listing to confirm) | W5: 7 kg over your limit, but best local service of any light EV
A6: 5 | B6: Ampere Magnus Neo (closest alternative) | C6: Standard | D6: EV | E6: 103 | F6: =IF(AND(E6>=Inputs!$B$18,E6<=Inputs!$B$19),"YES","No – "&TEXT(E6-Inputs!$B$19,"0.0")&" kg over") | G6: =E6-Inputs!$B$17 | H6: 2.3 | I6: 85 | J6: ~118 km IDC | K6: 65 | L6: n/a | M6: Not confirmed | N6: 5 h (0–80%) | O6: — | P6: Not confirmed | Q6: Not confirmed | R6: Not confirmed | S6: 30 | U6: 2.3 | V6: Not confirmed in Thoothukudi | W6: LFP battery (long life) but 103 kg and no confirmed dealer
A7: 6 | B7: Yamaha Fascino 125 Fi Hybrid (closest alternative) | C7: Drum | D7: Petrol | E7: 99 | F7: =IF(AND(E7>=Inputs!$B$18,E7<=Inputs!$B$19),"YES","No – "&TEXT(E7-Inputs!$B$19,"0.0")&" kg over") | G7: =E7-Inputs!$B$17 | H7: 125 | I7: 52 | J7: ~49 kmpl ARAI | K7: 90 | L7: 780 | M7: 21 L † | N7: — | O7: 5.2 | P7: Drum/drum, UBS combined braking † | Q7: 12-inch front † | R7: Confirm at dealer † | T7: 6 | V7: Lakhmi Motors (Tiruchendur Rd) – listed | W7: Lightest petrol SCOOTER on sale; peppy and frugal
A8: 7 | B8: Yamaha RayZR 125 Fi Hybrid (closest alternative) | C8: Drum | D8: Petrol | E8: 99 | F8: =IF(AND(E8>=Inputs!$B$18,E8<=Inputs!$B$19),"YES","No – "&TEXT(E8-Inputs!$B$19,"0.0")&" kg over") | G8: =E8-Inputs!$B$17 | H8: 125 | I8: 50 | J8: ~49 kmpl ARAI † | K8: 90 | L8: 785 | M8: 21 L † | N8: — | O8: 5.2 | P8: Drum/drum, UBS † | Q8: 12-inch front † | R8: Confirm at dealer † | T8: 6 | V8: Lakhmi Motors (Tiruchendur Rd) – listed | W8: Same engine as Fascino, sportier & firmer; small seat for pillion
A9: 8 | B9: TVS XL100 (moped) | C9: Heavy Duty i-Touchstart | D9: Petrol | E9: 89 | F9: =IF(AND(E9>=Inputs!$B$18,E9<=Inputs!$B$19),"YES","No – "&TEXT(E9-Inputs!$B$19,"0.0")&" kg over") | G9: =E9-Inputs!$B$17 | H9: 99.7 | I9: 57 | J9: 67 kmpl ARAI ✅ | K9: 60 | L9: n/a | M9: No boot (carrier/hook) | N9: — | O9: 4 | P9: Drum/drum † | Q9: 16-inch spoke † | R9: Confirm at dealer | T9: 3.2 | V9: TVS dealers listed in city | W9: Within 85–95 kg and cheapest – but a moped, not a scooter
A10: 9 | B10: TVS Zest 110 (closest alternative) | C10: Gloss | D10: Petrol | E10: 103 | F10: =IF(AND(E10>=Inputs!$B$18,E10<=Inputs!$B$19),"YES","No – "&TEXT(E10-Inputs!$B$19,"0.0")&" kg over") | G10: =E10-Inputs!$B$17 | H10: 109.7 | I10: 47 | J10: 45 kmpl ✅ | K10: 80 | L10: 760 | M10: 19 L † | N10: — | O10: 5 | P10: Drum/drum, combined braking † | Q10: 10-inch † | R10: Confirm at dealer | T10: 5.7 | V10: TVS dealers listed in city | W10: Low 760 mm seat, easy to handle; older design
A11: 10 | B11: Honda Dio 110 (closest alternative) | C11: STD | D11: Petrol | E11: 103 | F11: =IF(AND(E11>=Inputs!$B$18,E11<=Inputs!$B$19),"YES","No – "&TEXT(E11-Inputs!$B$19,"0.0")&" kg over") | G11: =E11-Inputs!$B$17 | H11: 109.51 | I11: 50 | J11: ~50 kmpl est. | K11: 83 | L11: 765 | M11: 18 L † | N11: — | O11: 5.3 | P11: Drum/drum, CBS † | Q11: 12-inch front / 10-inch rear † | R11: 3 yr + extended (Honda) † | T11: 5.7 | V11: Pearl Honda (Ettayapuram Rd) – listed | W11: Honda reliability in a lighter body than Activa
B13: Real-world range/mileage: Fascino 50–55 (owners), XL100 55–60 (owners) are reported figures; all other real-world numbers are ESTIMATES (≈75–80% of claimed for EVs).
B14: ✅ = confirmed in 2026 source; † = brochure figure not re-verified; 'Not confirmed' = could not find it – ask the dealer.
B15: NOT included: TVS Scooty Pep+ (93 kg) – discontinued Nov 2024. Low-speed EVs (Odysse V2 75 kg, Okaya ClassIQ, etc.) – max 25 km/h, not a real Pleasure replacement. Hero Electric Optima (93 kg) – company in insolvency. Ola S1 Z/Gig – weight not officially published, no confirmed Thoothukudi service.

Sheet Top 3 Variants
A1: Manufacturer | B1: Model | C1: Variant | D1: Type | E1: Kerb weight (kg) | F1: Battery / Engine | G1: Range / mileage | H1: Top speed | I1: Seat (mm) | J1: Storage | K1: Major features | L1: Ex-showroom (₹) | M1: On-road Thoothukudi (₹) | N1: Price status
A2: Honda | B2: QC1 | C2: Standard — ONLY ONE VARIANT EXISTS | D2: EV | E2: 89.5 | F2: 1.5 kWh fixed | G2: 80 km claimed / ~60 real | H2: 50 | I2: 705 | J2: 26 L | K2: LCD display, USB-C, fixed battery, 4h40 charge | L2: 90490 | M2: 97274 | N2: Thoothukudi listing (Autocar, 5 Jun 2026) ✅
A3: Honda | B3: Dio 110 | C3: STD | D3: Petrol | E3: 103 | F3: 109.5 cc | G3: ~50 kmpl | H3: 83 | I3: 765 | J3: 18 L | K3: CBS, idle-stop † | M3: 85473 | N3: Thoothukudi listing ✅
A4: Honda | B4: Dio 110 | C4: DLX | D4: Petrol | E4: 103 | F4: 109.5 cc | G4: ~50 kmpl | H4: 83 | I4: 765 | J4: 18 L | K4: Alloy wheels, digital meter † | L4: 88229 | M4: 92559 | N4: Thoothukudi listing ✅ (variant naming ⚠️)
A5: Honda | B5: Dio 110 | C5: H-Smart / top | D5: Petrol | E5: 103–105 † | F5: 109.5 cc | G5: ~50 kmpl | H5: 83 | I5: 765 | J5: 18 L | K5: Smart key † | M5: 98280 | N5: Thoothukudi listing ✅ (variant naming ⚠️)
A6: Kinetic | B6: DX | C6: DX 2.6 kWh | D6: EV | E6: 90 | F6: 2.6 kWh LFP | G6: 102 km claimed | H6: 80 | I6: n/a | J6: n/a | K6: 220mm front disc, CBS, 12-inch alloys | L6: 111499 | M6: 109000 | N6: ⚠️ Listing ₹1.09 L on-road is BELOW national ex-showroom – confirm
A7: Kinetic | B7: DX | C7: DX+ 2.6 kWh | D7: EV | E7: 90 | F7: 2.6 kWh LFP | G7: 116 km claimed | H7: 90 | I7: n/a | J7: n/a | K7: Higher power (6.4 bhp), more features | L7: 117499 | M7: 124000 | N7: Listing ₹1.24 L ✅; ex-showroom est. from ₹1.11–1.17 L range
A8: Kinetic | B8: DX | C8: DX 3.0 kWh / DX+ 3.5 kWh | D8: EV | E8: Not confirmed (likely >90) | F8: 3.0 / 3.5 kWh | G8: Not confirmed | H8: 80/90 | I8: n/a | J8: n/a | K8: Bigger battery | L8: 118000 | N8: Ex-showroom from ₹1.18 L / ₹1.27 L (Delhi) ✅; weight not confirmed
A9: Kinetic Green | B9: Zulu | C9: Standard — ONLY ONE VARIANT | D9: EV | E9: 93 | F9: 2.27 kWh | G9: 104 km claimed | H9: 60 | I9: n/a | J9: Front + under-seat | K9: Front bag hook, 160mm ground clearance | L9: 94990 | N9: No Thoothukudi listing – estimate on Price sheet
A10: TVS | B10: Orbiter | C10: V1 1.8 kWh — only V1 is near your weight | D10: EV | E10: 101 | F10: 1.8 kWh | G10: 86 km claimed | H10: 68 | I10: 760 | J10: 34 L | K10: Big boot, 14-inch front wheel † | L10: 88250 | N10: Estimate on Price sheet
A11: TVS | B11: Orbiter | C11: V2 3.1 kWh (112 kg – too heavy) | D11: EV | E11: 112 | F11: 3.1 kWh | G11: 158 km claimed | H11: n/a | I11: 760 | J11: 34 L | K11: More range | L11: 105000 | N11: Too heavy – shown for reference
A12: TVS | B12: XL100 | C12: Heavy Duty i-Touchstart | D12: Petrol | E12: 89 | F12: 99.7 cc | G12: 55–60 kmpl | H12: 60 | I12: n/a | J12: Carrier | K12: Electric start, heavy-duty carrier | L12: 56057 | M12: 70796 | N12: Thoothukudi listing ✅
A13: TVS | B13: XL100 | C13: Comfort i-Touchstart | D13: Petrol | E13: 88 | F13: 99.7 cc | G13: 55–60 kmpl | H13: 60 | I13: n/a | J13: Carrier | K13: Electric start, comfort seat | L13: 58514 | M13: 73285 | N13: Thoothukudi listing ✅
A14: TVS | B14: XL100 | C14: Heavy Duty Alloy | D14: Petrol | E14: 89 | F14: 99.7 cc | G14: 55–60 kmpl | H14: 60 | I14: n/a | J14: Carrier | K14: Alloy wheels (tubeless †) | L14: 60628 | M14: 74131 | N14: Thoothukudi listing ✅
A15: TVS | B15: Zest 110 | C15: Gloss | D15: Petrol | E15: 103 | F15: 109.7 cc | G15: 45 kmpl | H15: 80 | I15: 760 | J15: 19 L † | K15: Basic, light, low seat | L15: 70600 | M15: 87538 | N15: Thoothukudi breakdown ✅
A16: TVS | B16: Zest 110 | C16: Matte | D16: Petrol | E16: 103 | F16: 109.7 cc | G16: 45 kmpl | H16: 80 | I16: 760 | J16: 19 L † | K16: Matte paint | L16: 73135 | N16: Estimate
A17: TVS | B17: Zest 110 | C17: SXC | D17: Petrol | E17: 103 | F17: 109.7 cc | G17: 45 kmpl | H17: 80 | I17: 760 | J17: 19 L † | K17: Digital meter, LED features † | L17: 76520 | M17: 93000 | N17: Thoothukudi ≈ ₹93k listing ✅
A18: Yamaha | B18: Fascino 125 Fi Hybrid | C18: Drum | D18: Petrol | E18: 99 | F18: 125 cc hybrid | G18: ~52 kmpl | H18: 90 | I18: 780 | J18: 21 L † | K18: Hybrid assist, idle-stop † | L18: 81870 | M18: 96344 | N18: Thoothukudi breakdown ✅ (2 Aug 2026)
A19: Yamaha | B19: Fascino 125 Fi Hybrid | C19: Disc | D19: Petrol | E19: 99 † | F19: 125 cc hybrid | G19: ~52 kmpl | H19: 90 | I19: 780 | J19: 21 L † | K19: Front disc brake | M19: 107000 | N19: Thoothukudi listing ≈ ₹1.07 L ✅
A20: Yamaha | B20: Fascino 125 Fi Hybrid | C20: S | D20: Petrol | E20: 99 † | F20: 125 cc hybrid | G20: ~52 kmpl | H20: 90 | I20: 780 | J20: 21 L † | K20: Y-Connect Bluetooth †, answer-back | M20: 115687 | N20: Thoothukudi listing ✅
A21: Yamaha | B21: RayZR 125 Fi Hybrid | C21: Drum | D21: Petrol | E21: 99 | F21: 125 cc hybrid | G21: ~50 kmpl | H21: 90 | I21: 785 † | J21: 21 L † | K21: Sporty styling | M21: 93149 | N21: Chennai listing (same TN taxes) – proxy
A22: Yamaha | B22: RayZR 125 Fi Hybrid | C22: Disc / DLX Disc | D22: Petrol | E22: 99 † | F22: 125 cc hybrid | G22: ~50 kmpl | H22: 90 | I22: 785 † | J22: 21 L † | K22: Front disc | L22: 79958 | N22: Estimate
A23: Yamaha | B23: RayZR 125 Fi Hybrid | C23: Street Rally | D23: Petrol | E23: 99 † | F23: 125 cc hybrid | G23: ~50 kmpl | H23: 90 | I23: 785 † | J23: 21 L † | K23: Knobby-look tyres, styling | L23: 85974 | M23: 107670 | N23: Chennai listing – proxy
A24: Ampere | B24: Magnus Neo | C24: Standard — ONLY ONE VARIANT | D24: EV | E24: 103 | F24: 2.3 kWh LFP | G24: ~118 km IDC | H24: 65 | I24: n/a | J24: n/a | K24: LFP battery, updated 2026 | L24: 86999 | N24: Estimate on Price sheet
A26: Manufacturers with fewer than 3 suitable variants: Honda QC1 (1), Kinetic Green Zulu (1), Ampere Magnus Neo (1), TVS Orbiter (only V1 is light enough). Kinetic DX bigger-battery variants: weight not published.

Sheet Thoothukudi Price
A1: HOW MUCH MONEY DO I NEED? (variant used for costing; A+B+C+D = On-road; + E = Total)
A2: Scooter (variant) | B2: Type | C2: A. Ex-showroom (₹) | D2: B. RTO / registration (₹) | E2: C. Insurance yr-1 OD + 5-yr TP (₹) | F2: D. Other mandatory (HSRP, smart card, handling) (₹) | G2: F. ON-ROAD = A+B+C+D (₹) | H2: E. Basic accessories (₹) | I2: TOTAL MONEY NEEDED = F+E (₹) | J2: Status | K2: Note
A3: Honda QC1 (Standard) | B3: EV | C3: 90490 | D3: 1000 | E3: 5784 | F3: 0 | G3: =SUM(C3:F3) | H3: 1500 | I3: =G3+H3 | J3: Ex-showroom ✅ & on-road ₹97,274 ✅ (Thoothukudi); B/C split estimated | K3: Road tax ₹0 for EVs in TN till 31 Dec 2027
A4: Kinetic DX (2.6 kWh) | B4: EV | C4: 111499 | D4: 1000 | E4: 6500 | F4: 0 | G4: =SUM(C4:F4) | H4: 1500 | I4: =G4+H4 | J4: ESTIMATE (national ex-showroom); one listing shows ₹1.09 L on-road ⚠️ | K4: Road tax ₹0; insurance est.
A5: Kinetic Green Zulu | B5: EV | C5: 94990 | D5: 1000 | E5: 5800 | F5: 0 | G5: =SUM(C5:F5) | H5: 1500 | I5: =G5+H5 | J5: ESTIMATE | K5: Road tax ₹0
A6: TVS Orbiter V1 | B6: EV | C6: 88250 | D6: 1000 | E6: 5750 | F6: 2000 | G6: =SUM(C6:F6) | H6: 1500 | I6: =G6+H6 | J6: ESTIMATE (similar cities ₹98,369) | K6: Road tax ₹0
A7: Ampere Magnus Neo | B7: EV | C7: 86999 | D7: 1000 | E7: 5700 | F7: 0 | G7: =SUM(C7:F7) | H7: 1500 | I7: =G7+H7 | J7: ESTIMATE | K7: Road tax ₹0
A8: Yamaha Fascino 125 (Drum) | B8: Petrol | C8: 81870 | D8: 8187 | E8: 6287 | F8: 0 | G8: =SUM(C8:F8) | H8: 1500 | I8: =G8+H8 | J8: Thoothukudi breakdown ✅ (ZigWheels, 2 Aug 2026) | K8: TN road tax ~10% included in B
A9: Yamaha RayZR 125 (Drum) | B9: Petrol | C9: 79880 | D9: 8000 | E9: 5269 | F9: 0 | G9: =SUM(C9:F9) | H9: 1500 | I9: =G9+H9 | J9: ESTIMATE – Chennai on-road ₹93,149 ✅ used as total | K9: Same TN taxes as Thoothukudi
A10: TVS XL100 (HD i-Touchstart) | B10: Petrol | C10: 56057 | D10: 7500 | E10: 7239 | F10: 0 | G10: =SUM(C10:F10) | H10: 1500 | I10: =G10+H10 | J10: On-road ₹70,796 ✅ (Thoothukudi); B/C split estimated
A11: TVS Zest 110 (Gloss) | B11: Petrol | C11: 70600 | D11: 9635 | E11: 7303 | F11: 0 | G11: =SUM(C11:F11) | H11: 1500 | I11: =G11+H11 | J11: Thoothukudi breakdown ✅
A12: Honda Dio 110 (STD) | B12: Petrol | C12: 72500 | D12: 8000 | E12: 4973 | F12: 0 | G12: =SUM(C12:F12) | H12: 1500 | I12: =G12+H12 | J12: On-road ₹85,473 ✅ (Thoothukudi listing); A/B/C split estimated
A14: E. Accessories = ₹1,500 allowance for basic items (side/saree guard if not fitted, floor mat). A BIS helmet must be supplied by the manufacturer at purchase under Central Motor Vehicles Rules 138(4)(f) † – ask for it free.
A15: Refuse 'handling charges' – they are not a legal/mandatory charge. Ask for an itemised quote: ex-showroom, registration, insurance, accessories.
A16: Central PM E-DRIVE EV subsidy ENDED 31 Jul 2026 – EV prices above include no central subsidy. TN EV road tax = 0% (till 31 Dec 2027).

Sheet Running Cost
A1: FUEL / ELECTRICITY COST. EV: km × Wh/km ÷ 1000 × ₹/unit. Petrol: km ÷ kmpl × ₹/litre
A2: Scooter | B2: Type | C2: Cost per km (₹) | D2: LOW Daily | E2: LOW Monthly | F2: LOW Annual | G2: LOW 5-year | H2: LOW 10-year | I2: MEDIUM Daily | J2: MEDIUM Monthly | K2: MEDIUM Annual | L2: MEDIUM 5-year | M2: MEDIUM 10-year | N2: HIGH Daily | O2: HIGH Monthly | P2: HIGH Annual | Q2: HIGH 5-year | R2: HIGH 10-year
A3: =Shortlist!B2 | B3: =Shortlist!D2 | C3: =IF(B3="EV",Shortlist!S2/1000*Inputs!$B$5,Inputs!$B$4/Shortlist!I2) | D3: =$C3*Inputs!$B$6 | E3: =D3*Inputs!$B$10 | F3: =D3*Inputs!$B$9 | G3: =F3*5 | H3: =F3*10 | I3: =$C3*Inputs!$B$7 | J3: =I3*Inputs!$B$10 | K3: =I3*Inputs!$B$9 | L3: =K3*5 | M3: =K3*10 | N3: =$C3*Inputs!$B$8 | O3: =N3*Inputs!$B$10 | P3: =N3*Inputs!$B$9 | Q3: =P3*5 | R3: =P3*10
A4: =Shortlist!B3 | B4: =Shortlist!D3 | C4: =IF(B4="EV",Shortlist!S3/1000*Inputs!$B$5,Inputs!$B$4/Shortlist!I3) | D4: =$C4*Inputs!$B$6 | E4: =D4*Inputs!$B$10 | F4: =D4*Inputs!$B$9 | G4: =F4*5 | H4: =F4*10 | I4: =$C4*Inputs!$B$7 | J4: =I4*Inputs!$B$10 | K4: =I4*Inputs!$B$9 | L4: =K4*5 | M4: =K4*10 | N4: =$C4*Inputs!$B$8 | O4: =N4*Inputs!$B$10 | P4: =N4*Inputs!$B$9 | Q4: =P4*5 | R4: =P4*10
A5: =Shortlist!B4 | B5: =Shortlist!D4 | C5: =IF(B5="EV",Shortlist!S4/1000*Inputs!$B$5,Inputs!$B$4/Shortlist!I4) | D5: =$C5*Inputs!$B$6 | E5: =D5*Inputs!$B$10 | F5: =D5*Inputs!$B$9 | G5: =F5*5 | H5: =F5*10 | I5: =$C5*Inputs!$B$7 | J5: =I5*Inputs!$B$10 | K5: =I5*Inputs!$B$9 | L5: =K5*5 | M5: =K5*10 | N5: =$C5*Inputs!$B$8 | O5: =N5*Inputs!$B$10 | P5: =N5*Inputs!$B$9 | Q5: =P5*5 | R5: =P5*10
A6: =Shortlist!B5 | B6: =Shortlist!D5 | C6: =IF(B6="EV",Shortlist!S5/1000*Inputs!$B$5,Inputs!$B$4/Shortlist!I5) | D6: =$C6*Inputs!$B$6 | E6: =D6*Inputs!$B$10 | F6: =D6*Inputs!$B$9 | G6: =F6*5 | H6: =F6*10 | I6: =$C6*Inputs!$B$7 | J6: =I6*Inputs!$B$10 | K6: =I6*Inputs!$B$9 | L6: =K6*5 | M6: =K6*10 | N6: =$C6*Inputs!$B$8 | O6: =N6*Inputs!$B$10 | P6: =N6*Inputs!$B$9 | Q6: =P6*5 | R6: =P6*10
A7: =Shortlist!B6 | B7: =Shortlist!D6 | C7: =IF(B7="EV",Shortlist!S6/1000*Inputs!$B$5,Inputs!$B$4/Shortlist!I6) | D7: =$C7*Inputs!$B$6 | E7: =D7*Inputs!$B$10 | F7: =D7*Inputs!$B$9 | G7: =F7*5 | H7: =F7*10 | I7: =$C7*Inputs!$B$7 | J7: =I7*Inputs!$B$10 | K7: =I7*Inputs!$B$9 | L7: =K7*5 | M7: =K7*10 | N7: =$C7*Inputs!$B$8 | O7: =N7*Inputs!$B$10 | P7: =N7*Inputs!$B$9 | Q7: =P7*5 | R7: =P7*10
A8: =Shortlist!B7 | B8: =Shortlist!D7 | C8: =IF(B8="EV",Shortlist!S7/1000*Inputs!$B$5,Inputs!$B$4/Shortlist!I7) | D8: =$C8*Inputs!$B$6 | E8: =D8*Inputs!$B$10 | F8: =D8*Inputs!$B$9 | G8: =F8*5 | H8: =F8*10 | I8: =$C8*Inputs!$B$7 | J8: =I8*Inputs!$B$10 | K8: =I8*Inputs!$B$9 | L8: =K8*5 | M8: =K8*10 | N8: =$C8*Inputs!$B$8 | O8: =N8*Inputs!$B$10 | P8: =N8*Inputs!$B$9 | Q8: =P8*5 | R8: =P8*10
A9: =Shortlist!B8 | B9: =Shortlist!D8 | C9: =IF(B9="EV",Shortlist!S8/1000*Inputs!$B$5,Inputs!$B$4/Shortlist!I8) | D9: =$C9*Inputs!$B$6 | E9: =D9*Inputs!$B$10 | F9: =D9*Inputs!$B$9 | G9: =F9*5 | H9: =F9*10 | I9: =$C9*Inputs!$B$7 | J9: =I9*Inputs!$B$10 | K9: =I9*Inputs!$B$9 | L9: =K9*5 | M9: =K9*10 | N9: =$C9*Inputs!$B$8 | O9: =N9*Inputs!$B$10 | P9: =N9*Inputs!$B$9 | Q9: =P9*5 | R9: =P9*10
A10: =Shortlist!B9 | B10: =Shortlist!D9 | C10: =IF(B10="EV",Shortlist!S9/1000*Inputs!$B$5,Inputs!$B$4/Shortlist!I9) | D10: =$C10*Inputs!$B$6 | E10: =D10*Inputs!$B$10 | F10: =D10*Inputs!$B$9 | G10: =F10*5 | H10: =F10*10 | I10: =$C10*Inputs!$B$7 | J10: =I10*Inputs!$B$10 | K10: =I10*Inputs!$B$9 | L10: =K10*5 | M10: =K10*10 | N10: =$C10*Inputs!$B$8 | O10: =N10*Inputs!$B$10 | P10: =N10*Inputs!$B$9 | Q10: =P10*5 | R10: =P10*10
A11: =Shortlist!B10 | B11: =Shortlist!D10 | C11: =IF(B11="EV",Shortlist!S10/1000*Inputs!$B$5,Inputs!$B$4/Shortlist!I10) | D11: =$C11*Inputs!$B$6 | E11: =D11*Inputs!$B$10 | F11: =D11*Inputs!$B$9 | G11: =F11*5 | H11: =F11*10 | I11: =$C11*Inputs!$B$7 | J11: =I11*Inputs!$B$10 | K11: =I11*Inputs!$B$9 | L11: =K11*5 | M11: =K11*10 | N11: =$C11*Inputs!$B$8 | O11: =N11*Inputs!$B$10 | P11: =N11*Inputs!$B$9 | Q11: =P11*5 | R11: =P11*10
A12: =Shortlist!B11 | B12: =Shortlist!D11 | C12: =IF(B12="EV",Shortlist!S11/1000*Inputs!$B$5,Inputs!$B$4/Shortlist!I11) | D12: =$C12*Inputs!$B$6 | E12: =D12*Inputs!$B$10 | F12: =D12*Inputs!$B$9 | G12: =F12*5 | H12: =F12*10 | I12: =$C12*Inputs!$B$7 | J12: =I12*Inputs!$B$10 | K12: =I12*Inputs!$B$9 | L12: =K12*5 | M12: =K12*10 | N12: =$C12*Inputs!$B$8 | O12: =N12*Inputs!$B$10 | P12: =N12*Inputs!$B$9 | Q12: =P12*5 | R12: =P12*10
A14: Assumes today's petrol and electricity prices stay flat (no inflation). If petrol rises 3%/yr, petrol 10-year cost is ~15% higher.

Sheet Insurance 10Y
A1: INSURANCE – ESTIMATED PREMIUM EACH YEAR (₹, incl. 18% GST). Year 1 is already inside the on-road price.
A2: Scooter | B2: Type | C2: Ex-showroom (₹) | D2: TP rate used (₹/yr) | E2: Year 1 | F2: Year 2 | G2: Year 3 | H2: Year 4 | I2: Year 5 | J2: Year 6 | K2: Year 7 | L2: Year 8 | M2: Year 9 | N2: Year 10 | O2: Years 2–10 total (extra cash) | P2: All 10 years
A3: =Shortlist!B2 | B3: =Shortlist!D2 | C3: ='Thoothukudi Price'!C3 | D3: =IF(B3="EV",IF(Shortlist!T2>3,Inputs!$B$16,Inputs!$B$15),Inputs!$B$14) | E3: ='Thoothukudi Price'!E3 | F3: =ROUND($C3*Inputs!$B$25*Inputs!$B$12*(1-Inputs!$C$25)*(1+Inputs!$B$13)+IF(2>5,$D3*(1+Inputs!$B$13),0),0) | G3: =ROUND($C3*Inputs!$B$26*Inputs!$B$12*(1-Inputs!$C$26)*(1+Inputs!$B$13)+IF(3>5,$D3*(1+Inputs!$B$13),0),0) | H3: =ROUND($C3*Inputs!$B$27*Inputs!$B$12*(1-Inputs!$C$27)*(1+Inputs!$B$13)+IF(4>5,$D3*(1+Inputs!$B$13),0),0) | I3: =ROUND($C3*Inputs!$B$28*Inputs!$B$12*(1-Inputs!$C$28)*(1+Inputs!$B$13)+IF(5>5,$D3*(1+Inputs!$B$13),0),0) | J3: =ROUND($C3*Inputs!$B$29*Inputs!$B$12*(1-Inputs!$C$29)*(1+Inputs!$B$13)+IF(6>5,$D3*(1+Inputs!$B$13),0),0) | K3: =ROUND($C3*Inputs!$B$30*Inputs!$B$12*(1-Inputs!$C$30)*(1+Inputs!$B$13)+IF(7>5,$D3*(1+Inputs!$B$13),0),0) | L3: =ROUND($C3*Inputs!$B$31*Inputs!$B$12*(1-Inputs!$C$31)*(1+Inputs!$B$13)+IF(8>5,$D3*(1+Inputs!$B$13),0),0) | M3: =ROUND($C3*Inputs!$B$32*Inputs!$B$12*(1-Inputs!$C$32)*(1+Inputs!$B$13)+IF(9>5,$D3*(1+Inputs!$B$13),0),0) | N3: =ROUND($C3*Inputs!$B$33*Inputs!$B$12*(1-Inputs!$C$33)*(1+Inputs!$B$13)+IF(10>5,$D3*(1+Inputs!$B$13),0),0) | O3: =SUM(F3:N3) | P3: =SUM(E3:N3)
A4: =Shortlist!B3 | B4: =Shortlist!D3 | C4: ='Thoothukudi Price'!C4 | D4: =IF(B4="EV",IF(Shortlist!T3>3,Inputs!$B$16,Inputs!$B$15),Inputs!$B$14) | E4: ='Thoothukudi Price'!E4 | F4: =ROUND($C4*Inputs!$B$25*Inputs!$B$12*(1-Inputs!$C$25)*(1+Inputs!$B$13)+IF(2>5,$D4*(1+Inputs!$B$13),0),0) | G4: =ROUND($C4*Inputs!$B$26*Inputs!$B$12*(1-Inputs!$C$26)*(1+Inputs!$B$13)+IF(3>5,$D4*(1+Inputs!$B$13),0),0) | H4: =ROUND($C4*Inputs!$B$27*Inputs!$B$12*(1-Inputs!$C$27)*(1+Inputs!$B$13)+IF(4>5,$D4*(1+Inputs!$B$13),0),0) | I4: =ROUND($C4*Inputs!$B$28*Inputs!$B$12*(1-Inputs!$C$28)*(1+Inputs!$B$13)+IF(5>5,$D4*(1+Inputs!$B$13),0),0) | J4: =ROUND($C4*Inputs!$B$29*Inputs!$B$12*(1-Inputs!$C$29)*(1+Inputs!$B$13)+IF(6>5,$D4*(1+Inputs!$B$13),0),0) | K4: =ROUND($C4*Inputs!$B$30*Inputs!$B$12*(1-Inputs!$C$30)*(1+Inputs!$B$13)+IF(7>5,$D4*(1+Inputs!$B$13),0),0) | L4: =ROUND($C4*Inputs!$B$31*Inputs!$B$12*(1-Inputs!$C$31)*(1+Inputs!$B$13)+IF(8>5,$D4*(1+Inputs!$B$13),0),0) | M4: =ROUND($C4*Inputs!$B$32*Inputs!$B$12*(1-Inputs!$C$32)*(1+Inputs!$B$13)+IF(9>5,$D4*(1+Inputs!$B$13),0),0) | N4: =ROUND($C4*Inputs!$B$33*Inputs!$B$12*(1-Inputs!$C$33)*(1+Inputs!$B$13)+IF(10>5,$D4*(1+Inputs!$B$13),0),0) | O4: =SUM(F4:N4) | P4: =SUM(E4:N4)
A5: =Shortlist!B4 | B5: =Shortlist!D4 | C5: ='Thoothukudi Price'!C5 | D5: =IF(B5="EV",IF(Shortlist!T4>3,Inputs!$B$16,Inputs!$B$15),Inputs!$B$14) | E5: ='Thoothukudi Price'!E5 | F5: =ROUND($C5*Inputs!$B$25*Inputs!$B$12*(1-Inputs!$C$25)*(1+Inputs!$B$13)+IF(2>5,$D5*(1+Inputs!$B$13),0),0) | G5: =ROUND($C5*Inputs!$B$26*Inputs!$B$12*(1-Inputs!$C$26)*(1+Inputs!$B$13)+IF(3>5,$D5*(1+Inputs!$B$13),0),0) | H5: =ROUND($C5*Inputs!$B$27*Inputs!$B$12*(1-Inputs!$C$27)*(1+Inputs!$B$13)+IF(4>5,$D5*(1+Inputs!$B$13),0),0) | I5: =ROUND($C5*Inputs!$B$28*Inputs!$B$12*(1-Inputs!$C$28)*(1+Inputs!$B$13)+IF(5>5,$D5*(1+Inputs!$B$13),0),0) | J5: =ROUND($C5*Inputs!$B$29*Inputs!$B$12*(1-Inputs!$C$29)*(1+Inputs!$B$13)+IF(6>5,$D5*(1+Inputs!$B$13),0),0) | K5: =ROUND($C5*Inputs!$B$30*Inputs!$B$12*(1-Inputs!$C$30)*(1+Inputs!$B$13)+IF(7>5,$D5*(1+Inputs!$B$13),0),0) | L5: =ROUND($C5*Inputs!$B$31*Inputs!$B$12*(1-Inputs!$C$31)*(1+Inputs!$B$13)+IF(8>5,$D5*(1+Inputs!$B$13),0),0) | M5: =ROUND($C5*Inputs!$B$32*Inputs!$B$12*(1-Inputs!$C$32)*(1+Inputs!$B$13)+IF(9>5,$D5*(1+Inputs!$B$13),0),0) | N5: =ROUND($C5*Inputs!$B$33*Inputs!$B$12*(1-Inputs!$C$33)*(1+Inputs!$B$13)+IF(10>5,$D5*(1+Inputs!$B$13),0),0) | O5: =SUM(F5:N5) | P5: =SUM(E5:N5)
A6: =Shortlist!B5 | B6: =Shortlist!D5 | C6: ='Thoothukudi Price'!C6 | D6: =IF(B6="EV",IF(Shortlist!T5>3,Inputs!$B$16,Inputs!$B$15),Inputs!$B$14) | E6: ='Thoothukudi Price'!E6 | F6: =ROUND($C6*Inputs!$B$25*Inputs!$B$12*(1-Inputs!$C$25)*(1+Inputs!$B$13)+IF(2>5,$D6*(1+Inputs!$B$13),0),0) | G6: =ROUND($C6*Inputs!$B$26*Inputs!$B$12*(1-Inputs!$C$26)*(1+Inputs!$B$13)+IF(3>5,$D6*(1+Inputs!$B$13),0),0) | H6: =ROUND($C6*Inputs!$B$27*Inputs!$B$12*(1-Inputs!$C$27)*(1+Inputs!$B$13)+IF(4>5,$D6*(1+Inputs!$B$13),0),0) | I6: =ROUND($C6*Inputs!$B$28*Inputs!$B$12*(1-Inputs!$C$28)*(1+Inputs!$B$13)+IF(5>5,$D6*(1+Inputs!$B$13),0),0) | J6: =ROUND($C6*Inputs!$B$29*Inputs!$B$12*(1-Inputs!$C$29)*(1+Inputs!$B$13)+IF(6>5,$D6*(1+Inputs!$B$13),0),0) | K6: =ROUND($C6*Inputs!$B$30*Inputs!$B$12*(1-Inputs!$C$30)*(1+Inputs!$B$13)+IF(7>5,$D6*(1+Inputs!$B$13),0),0) | L6: =ROUND($C6*Inputs!$B$31*Inputs!$B$12*(1-Inputs!$C$31)*(1+Inputs!$B$13)+IF(8>5,$D6*(1+Inputs!$B$13),0),0) | M6: =ROUND($C6*Inputs!$B$32*Inputs!$B$12*(1-Inputs!$C$32)*(1+Inputs!$B$13)+IF(9>5,$D6*(1+Inputs!$B$13),0),0) | N6: =ROUND($C6*Inputs!$B$33*Inputs!$B$12*(1-Inputs!$C$33)*(1+Inputs!$B$13)+IF(10>5,$D6*(1+Inputs!$B$13),0),0) | O6: =SUM(F6:N6) | P6: =SUM(E6:N6)
A7: =Shortlist!B6 | B7: =Shortlist!D6 | C7: ='Thoothukudi Price'!C7 | D7: =IF(B7="EV",IF(Shortlist!T6>3,Inputs!$B$16,Inputs!$B$15),Inputs!$B$14) | E7: ='Thoothukudi Price'!E7 | F7: =ROUND($C7*Inputs!$B$25*Inputs!$B$12*(1-Inputs!$C$25)*(1+Inputs!$B$13)+IF(2>5,$D7*(1+Inputs!$B$13),0),0) | G7: =ROUND($C7*Inputs!$B$26*Inputs!$B$12*(1-Inputs!$C$26)*(1+Inputs!$B$13)+IF(3>5,$D7*(1+Inputs!$B$13),0),0) | H7: =ROUND($C7*Inputs!$B$27*Inputs!$B$12*(1-Inputs!$C$27)*(1+Inputs!$B$13)+IF(4>5,$D7*(1+Inputs!$B$13),0),0) | I7: =ROUND($C7*Inputs!$B$28*Inputs!$B$12*(1-Inputs!$C$28)*(1+Inputs!$B$13)+IF(5>5,$D7*(1+Inputs!$B$13),0),0) | J7: =ROUND($C7*Inputs!$B$29*Inputs!$B$12*(1-Inputs!$C$29)*(1+Inputs!$B$13)+IF(6>5,$D7*(1+Inputs!$B$13),0),0) | K7: =ROUND($C7*Inputs!$B$30*Inputs!$B$12*(1-Inputs!$C$30)*(1+Inputs!$B$13)+IF(7>5,$D7*(1+Inputs!$B$13),0),0) | L7: =ROUND($C7*Inputs!$B$31*Inputs!$B$12*(1-Inputs!$C$31)*(1+Inputs!$B$13)+IF(8>5,$D7*(1+Inputs!$B$13),0),0) | M7: =ROUND($C7*Inputs!$B$32*Inputs!$B$12*(1-Inputs!$C$32)*(1+Inputs!$B$13)+IF(9>5,$D7*(1+Inputs!$B$13),0),0) | N7: =ROUND($C7*Inputs!$B$33*Inputs!$B$12*(1-Inputs!$C$33)*(1+Inputs!$B$13)+IF(10>5,$D7*(1+Inputs!$B$13),0),0) | O7: =SUM(F7:N7) | P7: =SUM(E7:N7)
A8: =Shortlist!B7 | B8: =Shortlist!D7 | C8: ='Thoothukudi Price'!C8 | D8: =IF(B8="EV",IF(Shortlist!T7>3,Inputs!$B$16,Inputs!$B$15),Inputs!$B$14) | E8: ='Thoothukudi Price'!E8 | F8: =ROUND($C8*Inputs!$B$25*Inputs!$B$12*(1-Inputs!$C$25)*(1+Inputs!$B$13)+IF(2>5,$D8*(1+Inputs!$B$13),0),0) | G8: =ROUND($C8*Inputs!$B$26*Inputs!$B$12*(1-Inputs!$C$26)*(1+Inputs!$B$13)+IF(3>5,$D8*(1+Inputs!$B$13),0),0) | H8: =ROUND($C8*Inputs!$B$27*Inputs!$B$12*(1-Inputs!$C$27)*(1+Inputs!$B$13)+IF(4>5,$D8*(1+Inputs!$B$13),0),0) | I8: =ROUND($C8*Inputs!$B$28*Inputs!$B$12*(1-Inputs!$C$28)*(1+Inputs!$B$13)+IF(5>5,$D8*(1+Inputs!$B$13),0),0) | J8: =ROUND($C8*Inputs!$B$29*Inputs!$B$12*(1-Inputs!$C$29)*(1+Inputs!$B$13)+IF(6>5,$D8*(1+Inputs!$B$13),0),0) | K8: =ROUND($C8*Inputs!$B$30*Inputs!$B$12*(1-Inputs!$C$30)*(1+Inputs!$B$13)+IF(7>5,$D8*(1+Inputs!$B$13),0),0) | L8: =ROUND($C8*Inputs!$B$31*Inputs!$B$12*(1-Inputs!$C$31)*(1+Inputs!$B$13)+IF(8>5,$D8*(1+Inputs!$B$13),0),0) | M8: =ROUND($C8*Inputs!$B$32*Inputs!$B$12*(1-Inputs!$C$32)*(1+Inputs!$B$13)+IF(9>5,$D8*(1+Inputs!$B$13),0),0) | N8: =ROUND($C8*Inputs!$B$33*Inputs!$B$12*(1-Inputs!$C$33)*(1+Inputs!$B$13)+IF(10>5,$D8*(1+Inputs!$B$13),0),0) | O8: =SUM(F8:N8) | P8: =SUM(E8:N8)
A9: =Shortlist!B8 | B9: =Shortlist!D8 | C9: ='Thoothukudi Price'!C9 | D9: =IF(B9="EV",IF(Shortlist!T8>3,Inputs!$B$16,Inputs!$B$15),Inputs!$B$14) | E9: ='Thoothukudi Price'!E9 | F9: =ROUND($C9*Inputs!$B$25*Inputs!$B$12*(1-Inputs!$C$25)*(1+Inputs!$B$13)+IF(2>5,$D9*(1+Inputs!$B$13),0),0) | G9: =ROUND($C9*Inputs!$B$26*Inputs!$B$12*(1-Inputs!$C$26)*(1+Inputs!$B$13)+IF(3>5,$D9*(1+Inputs!$B$13),0),0) | H9: =ROUND($C9*Inputs!$B$27*Inputs!$B$12*(1-Inputs!$C$27)*(1+Inputs!$B$13)+IF(4>5,$D9*(1+Inputs!$B$13),0),0) | I9: =ROUND($C9*Inputs!$B$28*Inputs!$B$12*(1-Inputs!$C$28)*(1+Inputs!$B$13)+IF(5>5,$D9*(1+Inputs!$B$13),0),0) | J9: =ROUND($C9*Inputs!$B$29*Inputs!$B$12*(1-Inputs!$C$29)*(1+Inputs!$B$13)+IF(6>5,$D9*(1+Inputs!$B$13),0),0) | K9: =ROUND($C9*Inputs!$B$30*Inputs!$B$12*(1-Inputs!$C$30)*(1+Inputs!$B$13)+IF(7>5,$D9*(1+Inputs!$B$13),0),0) | L9: =ROUND($C9*Inputs!$B$31*Inputs!$B$12*(1-Inputs!$C$31)*(1+Inputs!$B$13)+IF(8>5,$D9*(1+Inputs!$B$13),0),0) | M9: =ROUND($C9*Inputs!$B$32*Inputs!$B$12*(1-Inputs!$C$32)*(1+Inputs!$B$13)+IF(9>5,$D9*(1+Inputs!$B$13),0),0) | N9: =ROUND($C9*Inputs!$B$33*Inputs!$B$12*(1-Inputs!$C$33)*(1+Inputs!$B$13)+IF(10>5,$D9*(1+Inputs!$B$13),0),0) | O9: =SUM(F9:N9) | P9: =SUM(E9:N9)
A10: =Shortlist!B9 | B10: =Shortlist!D9 | C10: ='Thoothukudi Price'!C10 | D10: =IF(B10="EV",IF(Shortlist!T9>3,Inputs!$B$16,Inputs!$B$15),Inputs!$B$14) | E10: ='Thoothukudi Price'!E10 | F10: =ROUND($C10*Inputs!$B$25*Inputs!$B$12*(1-Inputs!$C$25)*(1+Inputs!$B$13)+IF(2>5,$D10*(1+Inputs!$B$13),0),0) | G10: =ROUND($C10*Inputs!$B$26*Inputs!$B$12*(1-Inputs!$C$26)*(1+Inputs!$B$13)+IF(3>5,$D10*(1+Inputs!$B$13),0),0) | H10: =ROUND($C10*Inputs!$B$27*Inputs!$B$12*(1-Inputs!$C$27)*(1+Inputs!$B$13)+IF(4>5,$D10*(1+Inputs!$B$13),0),0) | I10: =ROUND($C10*Inputs!$B$28*Inputs!$B$12*(1-Inputs!$C$28)*(1+Inputs!$B$13)+IF(5>5,$D10*(1+Inputs!$B$13),0),0) | J10: =ROUND($C10*Inputs!$B$29*Inputs!$B$12*(1-Inputs!$C$29)*(1+Inputs!$B$13)+IF(6>5,$D10*(1+Inputs!$B$13),0),0) | K10: =ROUND($C10*Inputs!$B$30*Inputs!$B$12*(1-Inputs!$C$30)*(1+Inputs!$B$13)+IF(7>5,$D10*(1+Inputs!$B$13),0),0) | L10: =ROUND($C10*Inputs!$B$31*Inputs!$B$12*(1-Inputs!$C$31)*(1+Inputs!$B$13)+IF(8>5,$D10*(1+Inputs!$B$13),0),0) | M10: =ROUND($C10*Inputs!$B$32*Inputs!$B$12*(1-Inputs!$C$32)*(1+Inputs!$B$13)+IF(9>5,$D10*(1+Inputs!$B$13),0),0) | N10: =ROUND($C10*Inputs!$B$33*Inputs!$B$12*(1-Inputs!$C$33)*(1+Inputs!$B$13)+IF(10>5,$D10*(1+Inputs!$B$13),0),0) | O10: =SUM(F10:N10) | P10: =SUM(E10:N10)
A11: =Shortlist!B10 | B11: =Shortlist!D10 | C11: ='Thoothukudi Price'!C11 | D11: =IF(B11="EV",IF(Shortlist!T10>3,Inputs!$B$16,Inputs!$B$15),Inputs!$B$14) | E11: ='Thoothukudi Price'!E11 | F11: =ROUND($C11*Inputs!$B$25*Inputs!$B$12*(1-Inputs!$C$25)*(1+Inputs!$B$13)+IF(2>5,$D11*(1+Inputs!$B$13),0),0) | G11: =ROUND($C11*Inputs!$B$26*Inputs!$B$12*(1-Inputs!$C$26)*(1+Inputs!$B$13)+IF(3>5,$D11*(1+Inputs!$B$13),0),0) | H11: =ROUND($C11*Inputs!$B$27*Inputs!$B$12*(1-Inputs!$C$27)*(1+Inputs!$B$13)+IF(4>5,$D11*(1+Inputs!$B$13),0),0) | I11: =ROUND($C11*Inputs!$B$28*Inputs!$B$12*(1-Inputs!$C$28)*(1+Inputs!$B$13)+IF(5>5,$D11*(1+Inputs!$B$13),0),0) | J11: =ROUND($C11*Inputs!$B$29*Inputs!$B$12*(1-Inputs!$C$29)*(1+Inputs!$B$13)+IF(6>5,$D11*(1+Inputs!$B$13),0),0) | K11: =ROUND($C11*Inputs!$B$30*Inputs!$B$12*(1-Inputs!$C$30)*(1+Inputs!$B$13)+IF(7>5,$D11*(1+Inputs!$B$13),0),0) | L11: =ROUND($C11*Inputs!$B$31*Inputs!$B$12*(1-Inputs!$C$31)*(1+Inputs!$B$13)+IF(8>5,$D11*(1+Inputs!$B$13),0),0) | M11: =ROUND($C11*Inputs!$B$32*Inputs!$B$12*(1-Inputs!$C$32)*(1+Inputs!$B$13)+IF(9>5,$D11*(1+Inputs!$B$13),0),0) | N11: =ROUND($C11*Inputs!$B$33*Inputs!$B$12*(1-Inputs!$C$33)*(1+Inputs!$B$13)+IF(10>5,$D11*(1+Inputs!$B$13),0),0) | O11: =SUM(F11:N11) | P11: =SUM(E11:N11)
A12: =Shortlist!B11 | B12: =Shortlist!D11 | C12: ='Thoothukudi Price'!C12 | D12: =IF(B12="EV",IF(Shortlist!T11>3,Inputs!$B$16,Inputs!$B$15),Inputs!$B$14) | E12: ='Thoothukudi Price'!E12 | F12: =ROUND($C12*Inputs!$B$25*Inputs!$B$12*(1-Inputs!$C$25)*(1+Inputs!$B$13)+IF(2>5,$D12*(1+Inputs!$B$13),0),0) | G12: =ROUND($C12*Inputs!$B$26*Inputs!$B$12*(1-Inputs!$C$26)*(1+Inputs!$B$13)+IF(3>5,$D12*(1+Inputs!$B$13),0),0) | H12: =ROUND($C12*Inputs!$B$27*Inputs!$B$12*(1-Inputs!$C$27)*(1+Inputs!$B$13)+IF(4>5,$D12*(1+Inputs!$B$13),0),0) | I12: =ROUND($C12*Inputs!$B$28*Inputs!$B$12*(1-Inputs!$C$28)*(1+Inputs!$B$13)+IF(5>5,$D12*(1+Inputs!$B$13),0),0) | J12: =ROUND($C12*Inputs!$B$29*Inputs!$B$12*(1-Inputs!$C$29)*(1+Inputs!$B$13)+IF(6>5,$D12*(1+Inputs!$B$13),0),0) | K12: =ROUND($C12*Inputs!$B$30*Inputs!$B$12*(1-Inputs!$C$30)*(1+Inputs!$B$13)+IF(7>5,$D12*(1+Inputs!$B$13),0),0) | L12: =ROUND($C12*Inputs!$B$31*Inputs!$B$12*(1-Inputs!$C$31)*(1+Inputs!$B$13)+IF(8>5,$D12*(1+Inputs!$B$13),0),0) | M12: =ROUND($C12*Inputs!$B$32*Inputs!$B$12*(1-Inputs!$C$32)*(1+Inputs!$B$13)+IF(9>5,$D12*(1+Inputs!$B$13),0),0) | N12: =ROUND($C12*Inputs!$B$33*Inputs!$B$12*(1-Inputs!$C$33)*(1+Inputs!$B$13)+IF(10>5,$D12*(1+Inputs!$B$13),0),0) | O12: =SUM(F12:N12) | P12: =SUM(E12:N12)
A14: Year 1 = own-damage for 1 yr + third-party for 5 yrs (bundled in on-road price). Years 2–5: only own-damage renewal (third-party already paid). Years 6–10: own-damage + yearly third-party.
A15: Real premiums depend on: insurer, IDV you choose, No-Claim Bonus (NCB), add-ons (zero-dep, roadside assistance), Thoothukudi zone, vehicle age and any claims. Shop around each year – online renewals are often cheaper than the dealer's.
A16: EVs: third-party for ≤3 kW motors is cheaper (₹457 vs ₹714). Peak power used to pick the slab; where peak power is unknown, ≤3 kW slab used.

Sheet Maintenance 10Y
A1: MAINTENANCE ESTIMATE (₹) – Years 1–5 and Years 6–10, by usage level
A2: Item | B2: Applies to | C2: LOW yrs 1–5 | D2: LOW yrs 6–10 | E2: MED yrs 1–5 | F2: MED yrs 6–10 | G2: HIGH yrs 1–5 | H2: HIGH yrs 6–10
A3: =Inputs!A39 | B3: =Inputs!B39 | C3: =IF(ISNUMBER(Inputs!$D$39),INT((Inputs!$B$6*Inputs!$B$9*5)/Inputs!$D$39),INT(5/Inputs!$E$39))*Inputs!$C$39 | D3: =IF(ISNUMBER(Inputs!$D$39),(INT((Inputs!$B$6*Inputs!$B$9*10)/Inputs!$D$39)-INT((Inputs!$B$6*Inputs!$B$9*5)/Inputs!$D$39)),(INT(10/Inputs!$E$39)-INT(5/Inputs!$E$39)))*Inputs!$C$39 | E3: =IF(ISNUMBER(Inputs!$D$39),INT((Inputs!$B$7*Inputs!$B$9*5)/Inputs!$D$39),INT(5/Inputs!$E$39))*Inputs!$C$39 | F3: =IF(ISNUMBER(Inputs!$D$39),(INT((Inputs!$B$7*Inputs!$B$9*10)/Inputs!$D$39)-INT((Inputs!$B$7*Inputs!$B$9*5)/Inputs!$D$39)),(INT(10/Inputs!$E$39)-INT(5/Inputs!$E$39)))*Inputs!$C$39 | G3: =IF(ISNUMBER(Inputs!$D$39),INT((Inputs!$B$8*Inputs!$B$9*5)/Inputs!$D$39),INT(5/Inputs!$E$39))*Inputs!$C$39 | H3: =IF(ISNUMBER(Inputs!$D$39),(INT((Inputs!$B$8*Inputs!$B$9*10)/Inputs!$D$39)-INT((Inputs!$B$8*Inputs!$B$9*5)/Inputs!$D$39)),(INT(10/Inputs!$E$39)-INT(5/Inputs!$E$39)))*Inputs!$C$39
A4: =Inputs!A40 | B4: =Inputs!B40 | C4: =IF(ISNUMBER(Inputs!$D$40),INT((Inputs!$B$6*Inputs!$B$9*5)/Inputs!$D$40),INT(5/Inputs!$E$40))*Inputs!$C$40 | D4: =IF(ISNUMBER(Inputs!$D$40),(INT((Inputs!$B$6*Inputs!$B$9*10)/Inputs!$D$40)-INT((Inputs!$B$6*Inputs!$B$9*5)/Inputs!$D$40)),(INT(10/Inputs!$E$40)-INT(5/Inputs!$E$40)))*Inputs!$C$40 | E4: =IF(ISNUMBER(Inputs!$D$40),INT((Inputs!$B$7*Inputs!$B$9*5)/Inputs!$D$40),INT(5/Inputs!$E$40))*Inputs!$C$40 | F4: =IF(ISNUMBER(Inputs!$D$40),(INT((Inputs!$B$7*Inputs!$B$9*10)/Inputs!$D$40)-INT((Inputs!$B$7*Inputs!$B$9*5)/Inputs!$D$40)),(INT(10/Inputs!$E$40)-INT(5/Inputs!$E$40)))*Inputs!$C$40 | G4: =IF(ISNUMBER(Inputs!$D$40),INT((Inputs!$B$8*Inputs!$B$9*5)/Inputs!$D$40),INT(5/Inputs!$E$40))*Inputs!$C$40 | H4: =IF(ISNUMBER(Inputs!$D$40),(INT((Inputs!$B$8*Inputs!$B$9*10)/Inputs!$D$40)-INT((Inputs!$B$8*Inputs!$B$9*5)/Inputs!$D$40)),(INT(10/Inputs!$E$40)-INT(5/Inputs!$E$40)))*Inputs!$C$40
A5: =Inputs!A41 | B5: =Inputs!B41 | C5: =IF(ISNUMBER(Inputs!$D$41),INT((Inputs!$B$6*Inputs!$B$9*5)/Inputs!$D$41),INT(5/Inputs!$E$41))*Inputs!$C$41 | D5: =IF(ISNUMBER(Inputs!$D$41),(INT((Inputs!$B$6*Inputs!$B$9*10)/Inputs!$D$41)-INT((Inputs!$B$6*Inputs!$B$9*5)/Inputs!$D$41)),(INT(10/Inputs!$E$41)-INT(5/Inputs!$E$41)))*Inputs!$C$41 | E5: =IF(ISNUMBER(Inputs!$D$41),INT((Inputs!$B$7*Inputs!$B$9*5)/Inputs!$D$41),INT(5/Inputs!$E$41))*Inputs!$C$41 | F5: =IF(ISNUMBER(Inputs!$D$41),(INT((Inputs!$B$7*Inputs!$B$9*10)/Inputs!$D$41)-INT((Inputs!$B$7*Inputs!$B$9*5)/Inputs!$D$41)),(INT(10/Inputs!$E$41)-INT(5/Inputs!$E$41)))*Inputs!$C$41 | G5: =IF(ISNUMBER(Inputs!$D$41),INT((Inputs!$B$8*Inputs!$B$9*5)/Inputs!$D$41),INT(5/Inputs!$E$41))*Inputs!$C$41 | H5: =IF(ISNUMBER(Inputs!$D$41),(INT((Inputs!$B$8*Inputs!$B$9*10)/Inputs!$D$41)-INT((Inputs!$B$8*Inputs!$B$9*5)/Inputs!$D$41)),(INT(10/Inputs!$E$41)-INT(5/Inputs!$E$41)))*Inputs!$C$41
A6: =Inputs!A42 | B6: =Inputs!B42 | C6: =IF(ISNUMBER(Inputs!$D$42),INT((Inputs!$B$6*Inputs!$B$9*5)/Inputs!$D$42),INT(5/Inputs!$E$42))*Inputs!$C$42 | D6: =IF(ISNUMBER(Inputs!$D$42),(INT((Inputs!$B$6*Inputs!$B$9*10)/Inputs!$D$42)-INT((Inputs!$B$6*Inputs!$B$9*5)/Inputs!$D$42)),(INT(10/Inputs!$E$42)-INT(5/Inputs!$E$42)))*Inputs!$C$42 | E6: =IF(ISNUMBER(Inputs!$D$42),INT((Inputs!$B$7*Inputs!$B$9*5)/Inputs!$D$42),INT(5/Inputs!$E$42))*Inputs!$C$42 | F6: =IF(ISNUMBER(Inputs!$D$42),(INT((Inputs!$B$7*Inputs!$B$9*10)/Inputs!$D$42)-INT((Inputs!$B$7*Inputs!$B$9*5)/Inputs!$D$42)),(INT(10/Inputs!$E$42)-INT(5/Inputs!$E$42)))*Inputs!$C$42 | G6: =IF(ISNUMBER(Inputs!$D$42),INT((Inputs!$B$8*Inputs!$B$9*5)/Inputs!$D$42),INT(5/Inputs!$E$42))*Inputs!$C$42 | H6: =IF(ISNUMBER(Inputs!$D$42),(INT((Inputs!$B$8*Inputs!$B$9*10)/Inputs!$D$42)-INT((Inputs!$B$8*Inputs!$B$9*5)/Inputs!$D$42)),(INT(10/Inputs!$E$42)-INT(5/Inputs!$E$42)))*Inputs!$C$42
A7: =Inputs!A43 | B7: =Inputs!B43 | C7: =IF(ISNUMBER(Inputs!$D$43),INT((Inputs!$B$6*Inputs!$B$9*5)/Inputs!$D$43),INT(5/Inputs!$E$43))*Inputs!$C$43 | D7: =IF(ISNUMBER(Inputs!$D$43),(INT((Inputs!$B$6*Inputs!$B$9*10)/Inputs!$D$43)-INT((Inputs!$B$6*Inputs!$B$9*5)/Inputs!$D$43)),(INT(10/Inputs!$E$43)-INT(5/Inputs!$E$43)))*Inputs!$C$43 | E7: =IF(ISNUMBER(Inputs!$D$43),INT((Inputs!$B$7*Inputs!$B$9*5)/Inputs!$D$43),INT(5/Inputs!$E$43))*Inputs!$C$43 | F7: =IF(ISNUMBER(Inputs!$D$43),(INT((Inputs!$B$7*Inputs!$B$9*10)/Inputs!$D$43)-INT((Inputs!$B$7*Inputs!$B$9*5)/Inputs!$D$43)),(INT(10/Inputs!$E$43)-INT(5/Inputs!$E$43)))*Inputs!$C$43 | G7: =IF(ISNUMBER(Inputs!$D$43),INT((Inputs!$B$8*Inputs!$B$9*5)/Inputs!$D$43),INT(5/Inputs!$E$43))*Inputs!$C$43 | H7: =IF(ISNUMBER(Inputs!$D$43),(INT((Inputs!$B$8*Inputs!$B$9*10)/Inputs!$D$43)-INT((Inputs!$B$8*Inputs!$B$9*5)/Inputs!$D$43)),(INT(10/Inputs!$E$43)-INT(5/Inputs!$E$43)))*Inputs!$C$43
A8: =Inputs!A44 | B8: =Inputs!B44 | C8: =IF(ISNUMBER(Inputs!$D$44),INT((Inputs!$B$6*Inputs!$B$9*5)/Inputs!$D$44),INT(5/Inputs!$E$44))*Inputs!$C$44 | D8: =IF(ISNUMBER(Inputs!$D$44),(INT((Inputs!$B$6*Inputs!$B$9*10)/Inputs!$D$44)-INT((Inputs!$B$6*Inputs!$B$9*5)/Inputs!$D$44)),(INT(10/Inputs!$E$44)-INT(5/Inputs!$E$44)))*Inputs!$C$44 | E8: =IF(ISNUMBER(Inputs!$D$44),INT((Inputs!$B$7*Inputs!$B$9*5)/Inputs!$D$44),INT(5/Inputs!$E$44))*Inputs!$C$44 | F8: =IF(ISNUMBER(Inputs!$D$44),(INT((Inputs!$B$7*Inputs!$B$9*10)/Inputs!$D$44)-INT((Inputs!$B$7*Inputs!$B$9*5)/Inputs!$D$44)),(INT(10/Inputs!$E$44)-INT(5/Inputs!$E$44)))*Inputs!$C$44 | G8: =IF(ISNUMBER(Inputs!$D$44),INT((Inputs!$B$8*Inputs!$B$9*5)/Inputs!$D$44),INT(5/Inputs!$E$44))*Inputs!$C$44 | H8: =IF(ISNUMBER(Inputs!$D$44),(INT((Inputs!$B$8*Inputs!$B$9*10)/Inputs!$D$44)-INT((Inputs!$B$8*Inputs!$B$9*5)/Inputs!$D$44)),(INT(10/Inputs!$E$44)-INT(5/Inputs!$E$44)))*Inputs!$C$44
A9: =Inputs!A45 | B9: =Inputs!B45 | C9: =IF(ISNUMBER(Inputs!$D$45),INT((Inputs!$B$6*Inputs!$B$9*5)/Inputs!$D$45),INT(5/Inputs!$E$45))*Inputs!$C$45 | D9: =IF(ISNUMBER(Inputs!$D$45),(INT((Inputs!$B$6*Inputs!$B$9*10)/Inputs!$D$45)-INT((Inputs!$B$6*Inputs!$B$9*5)/Inputs!$D$45)),(INT(10/Inputs!$E$45)-INT(5/Inputs!$E$45)))*Inputs!$C$45 | E9: =IF(ISNUMBER(Inputs!$D$45),INT((Inputs!$B$7*Inputs!$B$9*5)/Inputs!$D$45),INT(5/Inputs!$E$45))*Inputs!$C$45 | F9: =IF(ISNUMBER(Inputs!$D$45),(INT((Inputs!$B$7*Inputs!$B$9*10)/Inputs!$D$45)-INT((Inputs!$B$7*Inputs!$B$9*5)/Inputs!$D$45)),(INT(10/Inputs!$E$45)-INT(5/Inputs!$E$45)))*Inputs!$C$45 | G9: =IF(ISNUMBER(Inputs!$D$45),INT((Inputs!$B$8*Inputs!$B$9*5)/Inputs!$D$45),INT(5/Inputs!$E$45))*Inputs!$C$45 | H9: =IF(ISNUMBER(Inputs!$D$45),(INT((Inputs!$B$8*Inputs!$B$9*10)/Inputs!$D$45)-INT((Inputs!$B$8*Inputs!$B$9*5)/Inputs!$D$45)),(INT(10/Inputs!$E$45)-INT(5/Inputs!$E$45)))*Inputs!$C$45
A10: =Inputs!A46 | B10: =Inputs!B46 | C10: =IF(ISNUMBER(Inputs!$D$46),INT((Inputs!$B$6*Inputs!$B$9*5)/Inputs!$D$46),INT(5/Inputs!$E$46))*Inputs!$C$46 | D10: =IF(ISNUMBER(Inputs!$D$46),(INT((Inputs!$B$6*Inputs!$B$9*10)/Inputs!$D$46)-INT((Inputs!$B$6*Inputs!$B$9*5)/Inputs!$D$46)),(INT(10/Inputs!$E$46)-INT(5/Inputs!$E$46)))*Inputs!$C$46 | E10: =IF(ISNUMBER(Inputs!$D$46),INT((Inputs!$B$7*Inputs!$B$9*5)/Inputs!$D$46),INT(5/Inputs!$E$46))*Inputs!$C$46 | F10: =IF(ISNUMBER(Inputs!$D$46),(INT((Inputs!$B$7*Inputs!$B$9*10)/Inputs!$D$46)-INT((Inputs!$B$7*Inputs!$B$9*5)/Inputs!$D$46)),(INT(10/Inputs!$E$46)-INT(5/Inputs!$E$46)))*Inputs!$C$46 | G10: =IF(ISNUMBER(Inputs!$D$46),INT((Inputs!$B$8*Inputs!$B$9*5)/Inputs!$D$46),INT(5/Inputs!$E$46))*Inputs!$C$46 | H10: =IF(ISNUMBER(Inputs!$D$46),(INT((Inputs!$B$8*Inputs!$B$9*10)/Inputs!$D$46)-INT((Inputs!$B$8*Inputs!$B$9*5)/Inputs!$D$46)),(INT(10/Inputs!$E$46)-INT(5/Inputs!$E$46)))*Inputs!$C$46
A11: =Inputs!A47 | B11: =Inputs!B47 | C11: =IF(ISNUMBER(Inputs!$D$47),INT((Inputs!$B$6*Inputs!$B$9*5)/Inputs!$D$47),INT(5/Inputs!$E$47))*Inputs!$C$47 | D11: =IF(ISNUMBER(Inputs!$D$47),(INT((Inputs!$B$6*Inputs!$B$9*10)/Inputs!$D$47)-INT((Inputs!$B$6*Inputs!$B$9*5)/Inputs!$D$47)),(INT(10/Inputs!$E$47)-INT(5/Inputs!$E$47)))*Inputs!$C$47 | E11: =IF(ISNUMBER(Inputs!$D$47),INT((Inputs!$B$7*Inputs!$B$9*5)/Inputs!$D$47),INT(5/Inputs!$E$47))*Inputs!$C$47 | F11: =IF(ISNUMBER(Inputs!$D$47),(INT((Inputs!$B$7*Inputs!$B$9*10)/Inputs!$D$47)-INT((Inputs!$B$7*Inputs!$B$9*5)/Inputs!$D$47)),(INT(10/Inputs!$E$47)-INT(5/Inputs!$E$47)))*Inputs!$C$47 | G11: =IF(ISNUMBER(Inputs!$D$47),INT((Inputs!$B$8*Inputs!$B$9*5)/Inputs!$D$47),INT(5/Inputs!$E$47))*Inputs!$C$47 | H11: =IF(ISNUMBER(Inputs!$D$47),(INT((Inputs!$B$8*Inputs!$B$9*10)/Inputs!$D$47)-INT((Inputs!$B$8*Inputs!$B$9*5)/Inputs!$D$47)),(INT(10/Inputs!$E$47)-INT(5/Inputs!$E$47)))*Inputs!$C$47
A12: =Inputs!A48 | B12: =Inputs!B48 | C12: =IF(ISNUMBER(Inputs!$D$48),INT((Inputs!$B$6*Inputs!$B$9*5)/Inputs!$D$48),INT(5/Inputs!$E$48))*Inputs!$C$48 | D12: =IF(ISNUMBER(Inputs!$D$48),(INT((Inputs!$B$6*Inputs!$B$9*10)/Inputs!$D$48)-INT((Inputs!$B$6*Inputs!$B$9*5)/Inputs!$D$48)),(INT(10/Inputs!$E$48)-INT(5/Inputs!$E$48)))*Inputs!$C$48 | E12: =IF(ISNUMBER(Inputs!$D$48),INT((Inputs!$B$7*Inputs!$B$9*5)/Inputs!$D$48),INT(5/Inputs!$E$48))*Inputs!$C$48 | F12: =IF(ISNUMBER(Inputs!$D$48),(INT((Inputs!$B$7*Inputs!$B$9*10)/Inputs!$D$48)-INT((Inputs!$B$7*Inputs!$B$9*5)/Inputs!$D$48)),(INT(10/Inputs!$E$48)-INT(5/Inputs!$E$48)))*Inputs!$C$48 | G12: =IF(ISNUMBER(Inputs!$D$48),INT((Inputs!$B$8*Inputs!$B$9*5)/Inputs!$D$48),INT(5/Inputs!$E$48))*Inputs!$C$48 | H12: =IF(ISNUMBER(Inputs!$D$48),(INT((Inputs!$B$8*Inputs!$B$9*10)/Inputs!$D$48)-INT((Inputs!$B$8*Inputs!$B$9*5)/Inputs!$D$48)),(INT(10/Inputs!$E$48)-INT(5/Inputs!$E$48)))*Inputs!$C$48
A13: =Inputs!A49 | B13: =Inputs!B49 | C13: =IF(ISNUMBER(Inputs!$D$49),INT((Inputs!$B$6*Inputs!$B$9*5)/Inputs!$D$49),INT(5/Inputs!$E$49))*Inputs!$C$49 | D13: =IF(ISNUMBER(Inputs!$D$49),(INT((Inputs!$B$6*Inputs!$B$9*10)/Inputs!$D$49)-INT((Inputs!$B$6*Inputs!$B$9*5)/Inputs!$D$49)),(INT(10/Inputs!$E$49)-INT(5/Inputs!$E$49)))*Inputs!$C$49 | E13: =IF(ISNUMBER(Inputs!$D$49),INT((Inputs!$B$7*Inputs!$B$9*5)/Inputs!$D$49),INT(5/Inputs!$E$49))*Inputs!$C$49 | F13: =IF(ISNUMBER(Inputs!$D$49),(INT((Inputs!$B$7*Inputs!$B$9*10)/Inputs!$D$49)-INT((Inputs!$B$7*Inputs!$B$9*5)/Inputs!$D$49)),(INT(10/Inputs!$E$49)-INT(5/Inputs!$E$49)))*Inputs!$C$49 | G13: =IF(ISNUMBER(Inputs!$D$49),INT((Inputs!$B$8*Inputs!$B$9*5)/Inputs!$D$49),INT(5/Inputs!$E$49))*Inputs!$C$49 | H13: =IF(ISNUMBER(Inputs!$D$49),(INT((Inputs!$B$8*Inputs!$B$9*10)/Inputs!$D$49)-INT((Inputs!$B$8*Inputs!$B$9*5)/Inputs!$D$49)),(INT(10/Inputs!$E$49)-INT(5/Inputs!$E$49)))*Inputs!$C$49
A14: =Inputs!A50 | B14: =Inputs!B50 | C14: =IF(ISNUMBER(Inputs!$D$50),INT((Inputs!$B$6*Inputs!$B$9*5)/Inputs!$D$50),INT(5/Inputs!$E$50))*Inputs!$C$50 | D14: =IF(ISNUMBER(Inputs!$D$50),(INT((Inputs!$B$6*Inputs!$B$9*10)/Inputs!$D$50)-INT((Inputs!$B$6*Inputs!$B$9*5)/Inputs!$D$50)),(INT(10/Inputs!$E$50)-INT(5/Inputs!$E$50)))*Inputs!$C$50 | E14: =IF(ISNUMBER(Inputs!$D$50),INT((Inputs!$B$7*Inputs!$B$9*5)/Inputs!$D$50),INT(5/Inputs!$E$50))*Inputs!$C$50 | F14: =IF(ISNUMBER(Inputs!$D$50),(INT((Inputs!$B$7*Inputs!$B$9*10)/Inputs!$D$50)-INT((Inputs!$B$7*Inputs!$B$9*5)/Inputs!$D$50)),(INT(10/Inputs!$E$50)-INT(5/Inputs!$E$50)))*Inputs!$C$50 | G14: =IF(ISNUMBER(Inputs!$D$50),INT((Inputs!$B$8*Inputs!$B$9*5)/Inputs!$D$50),INT(5/Inputs!$E$50))*Inputs!$C$50 | H14: =IF(ISNUMBER(Inputs!$D$50),(INT((Inputs!$B$8*Inputs!$B$9*10)/Inputs!$D$50)-INT((Inputs!$B$8*Inputs!$B$9*5)/Inputs!$D$50)),(INT(10/Inputs!$E$50)-INT(5/Inputs!$E$50)))*Inputs!$C$50
A15: =Inputs!A51 | B15: =Inputs!B51 | C15: =IF(ISNUMBER(Inputs!$D$51),INT((Inputs!$B$6*Inputs!$B$9*5)/Inputs!$D$51),INT(5/Inputs!$E$51))*Inputs!$C$51 | D15: =IF(ISNUMBER(Inputs!$D$51),(INT((Inputs!$B$6*Inputs!$B$9*10)/Inputs!$D$51)-INT((Inputs!$B$6*Inputs!$B$9*5)/Inputs!$D$51)),(INT(10/Inputs!$E$51)-INT(5/Inputs!$E$51)))*Inputs!$C$51 | E15: =IF(ISNUMBER(Inputs!$D$51),INT((Inputs!$B$7*Inputs!$B$9*5)/Inputs!$D$51),INT(5/Inputs!$E$51))*Inputs!$C$51 | F15: =IF(ISNUMBER(Inputs!$D$51),(INT((Inputs!$B$7*Inputs!$B$9*10)/Inputs!$D$51)-INT((Inputs!$B$7*Inputs!$B$9*5)/Inputs!$D$51)),(INT(10/Inputs!$E$51)-INT(5/Inputs!$E$51)))*Inputs!$C$51 | G15: =IF(ISNUMBER(Inputs!$D$51),INT((Inputs!$B$8*Inputs!$B$9*5)/Inputs!$D$51),INT(5/Inputs!$E$51))*Inputs!$C$51 | H15: =IF(ISNUMBER(Inputs!$D$51),(INT((Inputs!$B$8*Inputs!$B$9*10)/Inputs!$D$51)-INT((Inputs!$B$8*Inputs!$B$9*5)/Inputs!$D$51)),(INT(10/Inputs!$E$51)-INT(5/Inputs!$E$51)))*Inputs!$C$51
A16: =Inputs!A52 | B16: =Inputs!B52 | C16: =IF(ISNUMBER(Inputs!$D$52),INT((Inputs!$B$6*Inputs!$B$9*5)/Inputs!$D$52),INT(5/Inputs!$E$52))*Inputs!$C$52 | D16: =IF(ISNUMBER(Inputs!$D$52),(INT((Inputs!$B$6*Inputs!$B$9*10)/Inputs!$D$52)-INT((Inputs!$B$6*Inputs!$B$9*5)/Inputs!$D$52)),(INT(10/Inputs!$E$52)-INT(5/Inputs!$E$52)))*Inputs!$C$52 | E16: =IF(ISNUMBER(Inputs!$D$52),INT((Inputs!$B$7*Inputs!$B$9*5)/Inputs!$D$52),INT(5/Inputs!$E$52))*Inputs!$C$52 | F16: =IF(ISNUMBER(Inputs!$D$52),(INT((Inputs!$B$7*Inputs!$B$9*10)/Inputs!$D$52)-INT((Inputs!$B$7*Inputs!$B$9*5)/Inputs!$D$52)),(INT(10/Inputs!$E$52)-INT(5/Inputs!$E$52)))*Inputs!$C$52 | G16: =IF(ISNUMBER(Inputs!$D$52),INT((Inputs!$B$8*Inputs!$B$9*5)/Inputs!$D$52),INT(5/Inputs!$E$52))*Inputs!$C$52 | H16: =IF(ISNUMBER(Inputs!$D$52),(INT((Inputs!$B$8*Inputs!$B$9*10)/Inputs!$D$52)-INT((Inputs!$B$8*Inputs!$B$9*5)/Inputs!$D$52)),(INT(10/Inputs!$E$52)-INT(5/Inputs!$E$52)))*Inputs!$C$52
A18: TOTAL – EV | B18: EV | C18: =SUMIF($B$3:$B$16,"EV",C3:C16)+SUMIF($B$3:$B$16,"Both",C3:C16) | D18: =SUMIF($B$3:$B$16,"EV",D3:D16)+SUMIF($B$3:$B$16,"Both",D3:D16) | E18: =SUMIF($B$3:$B$16,"EV",E3:E16)+SUMIF($B$3:$B$16,"Both",E3:E16) | F18: =SUMIF($B$3:$B$16,"EV",F3:F16)+SUMIF($B$3:$B$16,"Both",F3:F16) | G18: =SUMIF($B$3:$B$16,"EV",G3:G16)+SUMIF($B$3:$B$16,"Both",G3:G16) | H18: =SUMIF($B$3:$B$16,"EV",H3:H16)+SUMIF($B$3:$B$16,"Both",H3:H16)
A19: TOTAL – Petrol | B19: Petrol | C19: =SUMIF($B$3:$B$16,"Petrol",C3:C16)+SUMIF($B$3:$B$16,"Both",C3:C16) | D19: =SUMIF($B$3:$B$16,"Petrol",D3:D16)+SUMIF($B$3:$B$16,"Both",D3:D16) | E19: =SUMIF($B$3:$B$16,"Petrol",E3:E16)+SUMIF($B$3:$B$16,"Both",E3:E16) | F19: =SUMIF($B$3:$B$16,"Petrol",F3:F16)+SUMIF($B$3:$B$16,"Both",F3:F16) | G19: =SUMIF($B$3:$B$16,"Petrol",G3:G16)+SUMIF($B$3:$B$16,"Both",G3:G16) | H19: =SUMIF($B$3:$B$16,"Petrol",H3:H16)+SUMIF($B$3:$B$16,"Both",H3:H16)
A21: 10-year maintenance (yrs 1–10) | C21: LOW | D21: MEDIUM | E21: HIGH
A22: EV | C22: =C18+D18 | D22: =E18+F18 | E22: =G18+H18
A23: Petrol | C23: =C19+D19 | D23: =E19+F19 | E23: =G19+H19
A25: EV battery replacement is NOT in this sheet – see 'Battery (EV)' sheet. Unit costs and intervals are on the Inputs sheet (rows 39+).

Sheet Battery (EV)
A1: EV BATTERY – best case vs conservative case
A2: EV | B2: Battery (kWh) | C2: Chemistry | D2: Warranty | E2: Replacement cost TODAY (est., ₹) = kWh × ₹/kWh | F2: Best case: replacement in 10 yrs (₹) | G2: Conservative: one replacement in 10 yrs (₹) | H2: Cycles needed in 10 yrs at MEDIUM use | I2: Note
A3: =Shortlist!B2 | B3: =Shortlist!U2 | C3: Not confirmed † | D3: Battery 3 yr/50,000 km † – confirm | E3: =B3*Inputs!$B$11 | F3: 0 | G3: =E3 | H3: =ROUND(Inputs!$B$7*Inputs!$B$9*10/Shortlist!I2,0) | I3: Fixed battery; Honda support depends on local EV service
A4: =Shortlist!B3 | B4: =Shortlist!U3 | C4: LFP ✅ | D4: Not confirmed | E4: =B4*Inputs!$B$11 | F4: 0 | G4: =E4 | H4: =ROUND(Inputs!$B$7*Inputs!$B$9*10/Shortlist!I3,0) | I4: LFP lasts longer (often 2,000+ cycles)
A5: =Shortlist!B4 | B5: =Shortlist!U4 | C5: Li-ion | D5: Not confirmed | E5: =B5*Inputs!$B$11 | F5: 0 | G5: =E5 | H5: =ROUND(Inputs!$B$7*Inputs!$B$9*10/Shortlist!I4,0) | I5: Small brand – parts availability risk in future
A6: =Shortlist!B5 | B6: =Shortlist!U5 | C6: Li-ion † | D6: TVS norm 3 yr/50,000 km † | E6: =B6*Inputs!$B$11 | F6: 0 | G6: =E6 | H6: =ROUND(Inputs!$B$7*Inputs!$B$9*10/Shortlist!I5,0) | I6: TVS has offered extended battery warranties on iQube (5 yr/70k)
A7: =Shortlist!B6 | B7: =Shortlist!U6 | C7: LFP ✅ | D7: Not confirmed | E7: =B7*Inputs!$B$11 | F7: 0 | G7: =E7 | H7: =ROUND(Inputs!$B$7*Inputs!$B$9*10/Shortlist!I6,0) | I7: LFP – long cycle life
A10: What you should know (simple):
A11: • Warranty: usually 3 years / 50,000 km; some brands sell extensions to 5 years / 70,000 km. Buy the extension if offered.
A12: • Life: a battery does not 'die' on a date. It slowly loses capacity. Typical Li-ion: ~800–1,000 full cycles to ~70–80% health; LFP: often 2,000+ cycles.
A13: • Example: at 30 km/day a 60 km-range scooter does ~1,800 full cycles in 10 years → likely below 70% by year 7–9 (Li-ion). An LFP pack may still be usable.
A14: • What shortens life: heat (Thoothukudi summers), charging right after a hot ride, keeping at 100% for long, deep 0% discharges, fast charging.
A15: • After 8–10 years: range may drop 25–40%. You can keep riding with less range, or replace the pack. Price today ~₹20,000/kWh – likely lower in future, but NOT guaranteed.
A16: • Support: TVS, Honda, Ather, Bajaj sell replacement packs through dealers. Small brands (Kinetic Green, Ampere) – check that parts will be available for 10 years.

Sheet 10-Year Total
A1: 10-YEAR TOTAL COST OF OWNERSHIP (₹) – does NOT subtract resale value
A2: Scooter | B2: Type | C2: Purchase (total money needed) | D2: LOW 20 km/day: Fuel/Electricity 10Y | E2: LOW 20 km/day: Maintenance 10Y | F2: LOW 20 km/day: Insurance yrs 2–10 | G2: LOW 20 km/day: Battery (conservative) | H2: LOW 20 km/day: TOTAL best case | I2: LOW 20 km/day: TOTAL conservative | J2: MED 30 km/day: Fuel/Electricity 10Y | K2: MED 30 km/day: Maintenance 10Y | L2: MED 30 km/day: Insurance yrs 2–10 | M2: MED 30 km/day: Battery (conservative) | N2: MED 30 km/day: TOTAL best case | O2: MED 30 km/day: TOTAL conservative | P2: HIGH 50 km/day: Fuel/Electricity 10Y | Q2: HIGH 50 km/day: Maintenance 10Y | R2: HIGH 50 km/day: Insurance yrs 2–10 | S2: HIGH 50 km/day: Battery (conservative) | T2: HIGH 50 km/day: TOTAL best case | U2: HIGH 50 km/day: TOTAL conservative
A3: =Shortlist!B2 | B3: =Shortlist!D2 | C3: ='Thoothukudi Price'!I3 | D3: ='Running Cost'!H3 | E3: =IF(B3="EV",'Maintenance 10Y'!$C$22,'Maintenance 10Y'!$C$23) | F3: ='Insurance 10Y'!O3 | G3: =IF(B3="EV",INDEX('Battery (EV)'!$G$3:$G$7,1),0) | H3: =$C3+D3+E3+F3 | I3: =H3+G3 | J3: ='Running Cost'!M3 | K3: =IF(B3="EV",'Maintenance 10Y'!$D$22,'Maintenance 10Y'!$D$23) | L3: ='Insurance 10Y'!O3 | M3: =IF(B3="EV",INDEX('Battery (EV)'!$G$3:$G$7,1),0) | N3: =$C3+J3+K3+L3 | O3: =N3+M3 | P3: ='Running Cost'!R3 | Q3: =IF(B3="EV",'Maintenance 10Y'!$E$22,'Maintenance 10Y'!$E$23) | R3: ='Insurance 10Y'!O3 | S3: =IF(B3="EV",INDEX('Battery (EV)'!$G$3:$G$7,1),0) | T3: =$C3+P3+Q3+R3 | U3: =T3+S3
A4: =Shortlist!B3 | B4: =Shortlist!D3 | C4: ='Thoothukudi Price'!I4 | D4: ='Running Cost'!H4 | E4: =IF(B4="EV",'Maintenance 10Y'!$C$22,'Maintenance 10Y'!$C$23) | F4: ='Insurance 10Y'!O4 | G4: =IF(B4="EV",INDEX('Battery (EV)'!$G$3:$G$7,2),0) | H4: =$C4+D4+E4+F4 | I4: =H4+G4 | J4: ='Running Cost'!M4 | K4: =IF(B4="EV",'Maintenance 10Y'!$D$22,'Maintenance 10Y'!$D$23) | L4: ='Insurance 10Y'!O4 | M4: =IF(B4="EV",INDEX('Battery (EV)'!$G$3:$G$7,2),0) | N4: =$C4+J4+K4+L4 | O4: =N4+M4 | P4: ='Running Cost'!R4 | Q4: =IF(B4="EV",'Maintenance 10Y'!$E$22,'Maintenance 10Y'!$E$23) | R4: ='Insurance 10Y'!O4 | S4: =IF(B4="EV",INDEX('Battery (EV)'!$G$3:$G$7,2),0) | T4: =$C4+P4+Q4+R4 | U4: =T4+S4
