Workbook

Sheet Executive Summary
A1: OnePlus Nord CE6 vs Best Phones Under ₹40,000 – Executive Summary
A2: Research date: 14-Oct-2026. Market: India (Tamil Nadu preference). Budget ≤ ₹40,000 regular price; ≥12GB physical RAM; CPU ≥ Snapdragon 7s Gen 4. Winners below are live formulas from the Scorecard sheet.
A4: BASELINE STATUS
A5: VERIFIED. OnePlus Nord CE6 launched in India on 7-May-2026 (sale 8-May). Snapdragon 7s Gen 4, 6.78" 1.5K 144Hz AMOLED, 8,000mAh (India) + 80W, IP66/68/69/69K, OxygenOS 16 / Android 16. IMPORTANT: it is sold only with 8GB RAM (8+128 / 8+256). No 12GB variant was found, so the baseline itself does not meet your 12GB requirement.
A7: Award | B7: Winning phone | C7: Variant | D7: Regular price (₹) | E7: Score (category / 100) | F7: Purchase link
A8: Best overall | B8: =Scorecard!D18 -> realme GT 7T 5G | C8: =Scorecard!E18 -> 12GB + 256GB | D8: =Scorecard!F18 -> 37999 | E8: =Scorecard!C18 -> 81 | F8: =INDEX(Scorecard!$W$5:$W$13,MATCH(B8,Scorecard!$B$5:$B$13,0)) -> Open listing / source
A9: Best processor & gaming | B9: =Scorecard!D19 -> OPPO K13 Turbo Pro 5G | C9: =Scorecard!E19 -> 12GB + 256GB | D9: =Scorecard!F19 -> 33999 | E9: =Scorecard!C19 -> 24 | F9: =INDEX(Scorecard!$W$5:$W$13,MATCH(B9,Scorecard!$B$5:$B$13,0)) -> Open listing / source
A10: Best camera | B10: =Scorecard!D21 -> Redmi Note 15 Pro+ 5G | C10: =Scorecard!E21 -> 12GB + 512GB | D10: =Scorecard!F21 -> 38990 | E10: =Scorecard!C21 -> 12 | F10: =INDEX(Scorecard!$W$5:$W$13,MATCH(B10,Scorecard!$B$5:$B$13,0)) -> Open listing / source
A11: Best battery & charging | B11: =Scorecard!D22 -> vivo T5 Pro 5G | C11: =Scorecard!E22 -> 12GB + 256GB | D11: =Scorecard!F22 -> 39999 | E11: =Scorecard!C22 -> 15 | F11: =INDEX(Scorecard!$W$5:$W$13,MATCH(B11,Scorecard!$B$5:$B$13,0)) -> Open listing / source
A12: Best display | B12: =Scorecard!D20 -> realme GT 7T 5G | C12: =Scorecard!E20 -> 12GB + 256GB | D12: =Scorecard!F20 -> 37999 | E12: =Scorecard!C20 -> 13 | F12: =INDEX(Scorecard!$W$5:$W$13,MATCH(B12,Scorecard!$B$5:$B$13,0)) -> Open listing / source
A13: Best software support | B13: =Scorecard!D23 -> Redmi Note 15 Pro+ 5G | C13: =Scorecard!E23 -> 12GB + 512GB | D13: =Scorecard!F23 -> 38990 | E13: =Scorecard!C23 -> 8 | F13: =INDEX(Scorecard!$W$5:$W$13,MATCH(B13,Scorecard!$B$5:$B$13,0)) -> Open listing / source
A14: Best build & durability | B14: =Scorecard!D24 -> POCO X8 Pro 5G | C14: =Scorecard!E24 -> 12GB + 256GB | D14: =Scorecard!F24 -> 39999 | E14: =Scorecard!C24 -> 5 | F14: =INDEX(Scorecard!$W$5:$W$13,MATCH(B14,Scorecard!$B$5:$B$13,0)) -> Open listing / source
A15: Best value for money | B15: =Scorecard!D26 -> iQOO Neo 10R 5G | C15: =Scorecard!E26 -> 12GB + 256GB | D15: =Scorecard!F26 -> 27990 | E15: =Scorecard!C26 -> 10 | F15: =INDEX(Scorecard!$W$5:$W$13,MATCH(B15,Scorecard!$B$5:$B$13,0)) -> Open listing / source
A17: FINAL RECOMMENDATION
A18: Buy the realme GT 7T (12GB + 256GB) at about ₹37,999 (Reliance Digital, MRP ₹42,999; Flipkart was seen at ₹36,990). It has the highest total score (see table above) and its price is among the most firmly verified. It is a clear step up from the Nord CE6: Dimensity 8400-Max (Geekbench 6 1660/6497 vs ~1100/3117), 12GB RAM, 120W charging (about 40 min to full), a 6,000-nit 1.5K panel, IP69, an 8MP ultrawide and security patches until May-2031. For the most raw gaming power at the lowest price, get the OPPO K13 Turbo Pro 12/256 (₹33,999, Snapdragon 8s Gen 4 with a cooling fan), if Flipkart has it in stock. If the POCO X8 Pro 12/256 stays at or below ₹40,000 on Flipkart, it is the newest strong alternative (2026, Dimensity 8500, IP69K). For camera, the best eligible options are the OnePlus Nord 5 (if you can find stock) or the Redmi Note 15 Pro+ 200MP. Note that the Motorola Edge 70 Pro is the better camera phone, but it costs about ₹43k.
A20: TOP 3 (eligible)
A21: Rank | B21: Model | C21: Variant | D21: Regular price (₹) | E21: Total /100 | F21: Link
A22: 1 | B22: =INDEX(Scorecard!$B$5:$B$13,MATCH(1,Scorecard!$U$5:$U$13,0)) -> realme GT 7T 5G | C22: =INDEX(Scorecard!$C$5:$C$13,MATCH(B22,Scorecard!$B$5:$B$13,0)) -> 12GB + 256GB | D22: =INDEX(Scorecard!$G$5:$G$13,MATCH(B22,Scorecard!$B$5:$B$13,0)) -> 37999 | E22: =INDEX(Scorecard!$P$5:$P$13,MATCH(B22,Scorecard!$B$5:$B$13,0)) -> 81 | F22: =INDEX(Scorecard!$W$5:$W$13,MATCH(B22,Scorecard!$B$5:$B$13,0)) -> Open listing / source
A23: 2 | B23: =INDEX(Scorecard!$B$5:$B$13,MATCH(2,Scorecard!$U$5:$U$13,0)) -> POCO X8 Pro 5G | C23: =INDEX(Scorecard!$C$5:$C$13,MATCH(B23,Scorecard!$B$5:$B$13,0)) -> 12GB + 256GB | D23: =INDEX(Scorecard!$G$5:$G$13,MATCH(B23,Scorecard!$B$5:$B$13,0)) -> 39999 | E23: =INDEX(Scorecard!$P$5:$P$13,MATCH(B23,Scorecard!$B$5:$B$13,0)) -> 79 | F23: =INDEX(Scorecard!$W$5:$W$13,MATCH(B23,Scorecard!$B$5:$B$13,0)) -> Open listing / source
A24: 3 | B24: =INDEX(Scorecard!$B$5:$B$13,MATCH(3,Scorecard!$U$5:$U$13,0)) -> OPPO K13 Turbo Pro 5G | C24: =INDEX(Scorecard!$C$5:$C$13,MATCH(B24,Scorecard!$B$5:$B$13,0)) -> 12GB + 256GB | D24: =INDEX(Scorecard!$G$5:$G$13,MATCH(B24,Scorecard!$B$5:$B$13,0)) -> 33999 | E24: =INDEX(Scorecard!$P$5:$P$13,MATCH(B24,Scorecard!$B$5:$B$13,0)) -> 78 | F24: =INDEX(Scorecard!$W$5:$W$13,MATCH(B24,Scorecard!$B$5:$B$13,0)) -> Open listing / source
A26: KEY LIMITATIONS
A27: 1. Direct access to Amazon, Flipkart, Croma, Reliance Digital and Vijay Sales was blocked from the research environment (network policy). Prices come from search-indexed retailer pages and price trackers (91mobiles, Smartprix, MySmartPrice, pricehistory). Exact time-of-day IST checks were not possible.
A28: 2. Indian phone prices rose repeatedly in 2026 (memory-cost hikes). Several 12GB variants show prices that conflict by ₹2–5k between sources. POCO X8 Pro and vivo T5 Pro are marked borderline: re-check that the price is ≤ ₹40,000 before you buy.
A29: 3. No Croma or Vijay Sales listing could be verified for any phone, apart from one Croma price for the GT 7T reported through Smartprix. Ask local stores in Tamil Nadu (Poorvika, Sangeetha, Croma, Reliance Digital) to match online prices.
A30: 4. Benchmark scores come from different reviewers, AnTuTu versions (v10 / v11) and test conditions. Treat them as rough tiers, not exact rankings.
A31: 5. Customer ratings are largely aggregator snapshots, which often combine variants. Review counts are shown wherever they were found.
A33: LEGEND
A34: Verified (official / retailer / independent test)
A35: Estimate, aggregator snapshot or conflicting sources
A36: Not found / unavailable / not accessible
A37: Conditional offer (bank / exchange / coupon)
A38: Category winner / qualifies
A39: Fails a mandatory rule (price > ₹40,000, RAM < 12GB, CPU below baseline)

Sheet Baseline Nord CE6
A1: Baseline – OnePlus Nord CE6 (verified)
A2: Exact model: OnePlus Nord CE6 (Nord CE 6 5G). Do not confuse it with the Nord CE6 Lite (Dimensity 7400 Apex, LCD) or the Nord 6 (Snapdragon 8s Gen 4, 9,000mAh).
A4: Attribute | B4: Verified value | C4: Status | D4: Source
A5: Commercial name | B5: OnePlus Nord CE6 (listed as 'OnePlus Nord CE 6 5G') | C5: Verified | D5: https://www.oneplus.com/global/nord-ce6/specs
A6: Announcement / launch (India) | B6: 7-May-2026; first sale 8-May-2026 12 PM IST (Amazon, OnePlus.in) | C6: Verified | D6: https://tech.sportskeeda.com/mobiles/oneplus-nord-ce6-series-launched-india-specs-features-price
A7: Launch price | B7: 8GB+128GB ₹29,999; 8GB+256GB ₹32,999 (₹2,000 early-bird bank discount) | C7: Verified | D7: https://www.tech2.com/mobile/oneplus-nord-ce-6-and-nord-ce-6-lite-with-8000mah-battery-launched-in-india-price-specs-text-10080729.html
A8: Price hikes | B8: OnePlus raised prices twice. 8GB+256GB is now ₹36,999 on OnePlus.in (₹4,000 above launch) | C8: Verified (news) | D8: https://www.mymobileindia.com/oneplus-nord-ce-6-gets-another-price-hike-in-india-now-costs-rs-4000-more-than-launch-price/
A9: Current price – 8+128 | B9: Amazon ₹34,999 (MRP ₹40,999); Flipkart ₹36,197 | C9: Retailer snapshot | D9: https://www.amazon.in/OnePlus-Snapdragon-Segments-Fastest-Response/dp/B0GWLHVJRH
A10: Current price – 8+256 | B10: ₹36,999 (Amazon lowest per MySmartPrice; 91mobiles saw ₹38,999) | C10: Aggregator snapshot | D10: https://www.mysmartprice.com/mobile/oneplus-nord-ce-6-5g-256gb-msp620884
A11: Physical RAM variants | B11: 8GB only (LPDDR4X). No 12GB variant found. 12GB listings found were for the separate Nord 6 | C11: Verified (no 12GB listing exists) | D11: https://www.smartprix.com/mobiles/oneplus-nord-ce-6-5g-8gb-ram-256gb-ppd1d6l6a324
A12: Storage | B12: 128GB / 256GB | C12: Verified | D12: https://www.digit.in/mobiles/oneplus-nord-ce-6.html
A13: Chipset | B13: Qualcomm Snapdragon 7s Gen 4 (4nm). CPU 1×2.7GHz A720 + 3×2.4GHz A720 + 4×1.8GHz A520. GPU Adreno 810 | C13: Verified (chip); core layout per Qualcomm spec | D13: https://gadgets.beebom.com/mobile/oneplus-nord-ce-6
A14: Display | B14: 6.78" 1.5K AMOLED, 144Hz; 800 nits typical, 1,800 nits HBM, 3,600 nits peak | C14: Verified | D14: https://www.gsmarena.com/oneplus_nord_ce6_5g-14611.php
A15: Rear cameras | B15: 50MP OmniVision OV50D40 f/1.8 with OIS + 2MP auxiliary. No ultrawide | C15: Verified | D15: https://www.gsmarena.com/oneplus_nord_ce6-review-2961p5.php
... A28: Review verdict | B28: Smartprix: battery, durability and display are strong; camera decisions are confusing. Beebom: trails the vivo T5 Pro in benchmarks | C28: Independent review | D28: https://www.smartprix.com/bytes/oneplus-nord-ce6-review-with-pros-and-cons/
A30: LEGEND
A31: Verified (official / retailer / independent test)
A32: Estimate, aggregator snapshot or conflicting sources
A33: Not found / unavailable / not accessible
A34: Conditional offer (bank / exchange / coupon)
A35: Category winner / qualifies
A36: Fails a mandatory rule (price > ₹40,000, RAM < 12GB, CPU below baseline)

Sheet Retail Prices
A1: Retail Price Comparison – Amazon · Flipkart · Croma · Reliance Digital · Vijay Sales
A2: Checked 14-Oct-2026 (IST); via web-search index snapshots. Live retailer pages could not be opened directly (blocked by the research environment's network policy). Values are retailer-page snapshots or price-tracker figures, as labelled. Regular price excludes bank and exchange offers. 'Not verified' means no listing could be confirmed.
A4: Model | B4: Variant | C4: Retailer | D4: MRP (₹) | E4: Listed price (₹) | F4: Bank offer | G4: Exchange offer | H4: Coupon | I4: Effective price after offer (₹) | J4: Seller | K4: Availability | L4: Data status | M4: Date/time checked | N4: Link | O4: Notes
A5: OnePlus Nord CE6 | B5: 8GB+128GB | C5: Amazon India | D5: 40999 | E5: 34999 | F5: Not captured | G5: Available (conditional) | H5: None found | I5: Not found | J5: Amazon / OnePlus authorised | K5: In stock (snapshot) | L5: Retailer snapshot | M5: 14-Oct-2026 (IST); via web-search index snapshots | N5: https://www.amazon.in/OnePlus-Snapdragon-Segments-Fastest-Response/dp/B0GWLHVJRH | O5: Listing snapshot shows ₹34,999 vs list ₹40,999
A6: OnePlus Nord CE6 | B6: 8GB+256GB | C6: Amazon India | D6: Not found | E6: 36999 | F6: Not captured | G6: Available (conditional) | H6: None found | I6: Not found | J6: Amazon | K6: In stock (aggregator) | L6: Aggregator (MySmartPrice) | M6: 14-Oct-2026 (IST); via web-search index snapshots | N6: https://www.mysmartprice.com/mobile/oneplus-nord-ce-6-5g-256gb-msp620884 | O6: 91mobiles saw ₹38,999 on Amazon
A7: OnePlus Nord CE6 | B7: 8GB+128GB | C7: Flipkart | D7: Not found | E7: 36197 | F7: Not captured | G7: Available (conditional) | H7: None found | I7: 33912 | J7: Flipkart seller | K7: In stock (snapshot) | L7: Retailer snapshot | M7: 14-Oct-2026 (IST); via web-search index snapshots | N7: https://www.flipkart.com/oneplus-nord-ce6-pitch-black-128-gb/p/itmd7b224b18cb05 | O7: 'Buy at ₹33,912' shown with offers (conditional)
A8: OnePlus Nord CE6 | B8: 8GB+256GB | C8: Croma | D8: Not found | F8: Not verified | G8: Not verified | H8: Not verified | I8: Not found | J8: Not verified | K8: Not verified | L8: Not verified | M8: 14-Oct-2026 (IST); via web-search index snapshots | N8: https://www.croma.com/ | O8: No indexed listing found
A9: OnePlus Nord CE6 | B9: 8GB+256GB | C9: Reliance Digital | D9: Not found | F9: Not verified | G9: Not verified | H9: Not verified | I9: Not found | J9: Not verified | K9: Not verified | L9: Not verified | M9: 14-Oct-2026 (IST); via web-search index snapshots | N9: https://www.reliancedigital.in/ | O9: No indexed listing found
A10: OnePlus Nord CE6 | B10: 8GB+256GB | C10: Vijay Sales | D10: Not found | F10: Not verified | G10: Not verified | H10: Not verified | I10: Not found | J10: Not verified | K10: Not verified | L10: Not verified | M10: 14-Oct-2026 (IST); via web-search index snapshots | N10: https://www.vijaysales.com/ | O10: No indexed listing found
A11: OPPO K13 Turbo Pro | B11: 12GB+256GB | C11: Flipkart | D11: 44999 | E11: 33999 | F11: ₹1,700 bank offer | G11: Available (conditional) | H11: None found | I11: 32299 | J11: Flipkart (exclusive) | K11: Intermittently OUT OF STOCK | L11: Retailer snapshot + tracker (6-Oct-2026) | M11: 14-Oct-2026 (IST); via web-search index snapshots | N11: https://www.flipkart.com/oppo-k13-turbo-pro-5g-silver-knight-256-gb/p/itmeefeb718f01fe | O11: Tracker low ₹31,499 (28-Aug-2026, sale)
A12: OPPO K13 Turbo Pro | B12: 12GB+256GB | C12: Amazon / Croma / Reliance / Vijay Sales | D12: Not found | F12: Not verified | G12: Not verified | H12: Not verified | I12: Not found | J12: — | K12: Flipkart-exclusive model | L12: Not available | M12: 14-Oct-2026 (IST); via web-search index snapshots | N12: https://www.flipkart.com/search?q=oppo+k13+turbo+pro | O12: Sold online only through Flipkart
A13: iQOO Neo 10R | B13: 12GB+256GB | C13: Flipkart | D13: Not found | E13: 27990 | F13: Not captured | G13: Available (conditional) | H13: Not verified | I13: Not found | J13: Flipkart seller | K13: Listed | L13: Aggregator (91mobiles / Digit) | M13: 14-Oct-2026 (IST); via web-search index snapshots | N13: https://www.91mobiles.com/iqoo-neo-10r-price-in-india | O13: Lowest verified regular price in this study
A14: iQOO Neo 10R | B14: 12GB+256GB | C14: Amazon India | D14: Not found | E14: 30999 | F14: Not captured | G14: Available (conditional) | H14: Not verified | I14: Not found | J14: Amazon (iQOO official) | K14: Listed | L14: Price tracker (10-Oct-2026) | M14: 14-Oct-2026 (IST); via web-search index snapshots | N14: https://pricehistory.app/p/iqoo-neo-10r-5g-raging-blue-12gb-xlkyfzSj | O14: Tracker low ₹26,998
A15: iQOO Neo 10R | B15: 12GB+256GB | C15: Croma / Reliance / Vijay Sales | D15: Not found | F15: Not verified | G15: Not verified | H15: Not verified | I15: Not found | J15: Not verified | K15: Not verified | L15: Not verified | M15: 14-Oct-2026 (IST); via web-search index snapshots | N15: https://www.croma.com/ | O15: —
A16: realme GT 7T | B16: 12GB+256GB | C16: Reliance Digital | D16: 42999 | E16: 37999 | F16: Not captured | G16: Available (conditional) | H16: Not verified | I16: Not found | J16: Reliance Digital | K16: Listed (online + stores) | L16: Retailer snapshot | M16: 14-Oct-2026 (IST); via web-search index snapshots | N16: https://www.reliancedigital.in/product/realme-gt-7t-5g-256-gb-12-gb-ram-blue-mobile-phone-mbgan1-9247285 | O16: Black variant also ₹37,999. Good for Tamil Nadu store pickup
A17: realme GT 7T | B17: 12GB+256GB | C17: Flipkart | D17: Not found | E17: 36990 | F17: Not captured | G17: Available (conditional) | H17: Not verified | I17: Not found | J17: Flipkart seller | K17: Listed | L17: CONFLICTING (91mobiles ₹36,990 vs Smartprix ₹42,999) | M17: 14-Oct-2026 (IST); via web-search index snapshots | N17: https://www.91mobiles.com/realme-gt-7t-price-in-india | O17: Use the lower figure only if the live page confirms it
A18: realme GT 7T | B18: 12GB+256GB | C18: Amazon India | D18: 42999 | E18: 38990 | F18: Not captured | G18: Available (conditional) | H18: Not verified | I18: Not found | J18: Amazon | K18: In stock | L18: Aggregator (Smartprix 6-Oct-2026); product page snapshot ₹41,475 | M18: 14-Oct-2026 (IST); via web-search index snapshots | N18: https://www.amazon.in/realme-IceSense-MediaTek-Strongest-Graphene/dp/B0F6YWDMXF | O18: —
A19: realme GT 7T | B19: 12GB+256GB | C19: Croma | D19: Not found | E19: 40999 | F19: Not verified | G19: Not verified | H19: Not verified | I19: Not found | J19: Croma | K19: Listed | L19: Aggregator (Smartprix) | M19: 14-Oct-2026 (IST); via web-search index snapshots | N19: https://www.smartprix.com/mobiles/realme-gt-7t-12gb-ram-256gb-ppd1gzorx7ts | O19: Above budget at Croma
A20: realme GT 7T | B20: 12GB+256GB | C20: Vijay Sales | D20: Not found | F20: Not verified | G20: Not verified | H20: Not verified | I20: Not found | J20: Not verified | K20: Not verified | L20: Not verified | M20: 14-Oct-2026 (IST); via web-search index snapshots | N20: https://www.vijaysales.com/ | O20: —
A21: OnePlus Nord 5 | B21: 12GB+256GB | C21: Retailer not identified | D21: Not found | E21: 36999 | F21: Not verified | G21: Not verified | H21: Not verified | I21: Not found | J21: Not verified | K21: Stock doubtful | L21: Aggregator (Bajaj Finserv Oct-2026) | M21: 14-Oct-2026 (IST); via web-search index snapshots | N21: https://www.bajajfinserv.in/oneplus-nord-5-price-in-india | O21: Smartprix: ₹32,128 OUT OF STOCK (last change 18-Jun-2026)
A22: OnePlus Nord 5 | B22: 12GB+256GB | C22: Amazon India | D22: Not found | F22: Not verified | G22: Not verified | H22: Not verified | I22: Not found | J22: Not verified | K22: Not listed in Amazon search | L22: Not found | M22: 14-Oct-2026 (IST); via web-search index snapshots | N22: https://www.amazon.in/oneplus-nord-5-12gb-256gb/s?k=oneplus+nord+5+12gb+256gb | O22: Search returned Nord 6 / 15R instead
A23: POCO X8 Pro | B23: 12GB+256GB | C23: Flipkart | D23: Not found | E23: 39999 | F23: Not captured | G23: Available (conditional) | H23: Not verified | I23: Not found | J23: Flipkart | K23: Listed | L23: CONFLICTING (Smartprix ₹39,999 vs 91mobiles ₹41,999–42,999) | M23: 14-Oct-2026 (IST); via web-search index snapshots | N23: https://www.smartprix.com/mobiles/poco-x8-pro-5g-12gb-ram-256gb-ppd15mvem8mu | O23: Borderline. Launch price was ₹35,999
A24: POCO X8 Pro | B24: 12GB+256GB | C24: Amazon / Croma / Reliance / Vijay Sales | D24: Not found | F24: Not verified | G24: Not verified | H24: Not verified | I24: Not found | J24: Not verified | K24: Not verified | L24: Not verified | M24: 14-Oct-2026 (IST); via web-search index snapshots | N24: https://www.91mobiles.com/poco-x8-pro-price-in-india | O24: Amazon listed the 8GB variant at ₹38,890
A25: Redmi Note 15 Pro+ | B25: 12GB+512GB | C25: Flipkart | D25: 44990 | E25: 38990 | F25: Not captured | G25: Available (conditional) | H25: Not verified | I25: Not found | J25: Flipkart seller | K25: Listed | L25: Retailer snapshot | M25: 14-Oct-2026 (IST); via web-search index snapshots | N25: https://www.flipkart.com/redmi-note-15-pro-5g-carbon-black-512-gb/p/itm3174106e5bf60 | O25: Launch price ₹43,999
A26: Redmi Note 15 Pro+ | B26: 12GB+512GB | C26: Amazon India | D26: Not found | E26: 44999 | F26: Not verified | G26: Not verified | H26: Not verified | I26: Not found | J26: Amazon | K26: Listed | L26: Aggregator (91mobiles 13-Oct-2026) | M26: 14-Oct-2026 (IST); via web-search index snapshots | N26: https://www.91mobiles.com/xiaomi-redmi-note-15-pro-plus-price-in-india | O26: Above budget on Amazon
A27: vivo T5 Pro | B27: 12GB+256GB | C27: Flipkart | D27: Not found | E27: 39999 | F27: ₹3,000 instant bank discount (launch) | G27: Available (conditional) | H27: Not verified | I27: 36999 | J27: Flipkart | K27: Listed | L27: CONFLICTING (₹39,999 vs Smartprix Flipkart ₹41,999) | M27: 14-Oct-2026 (IST); via web-search index snapshots | N27: https://www.91mobiles.com/vivo-t5-pro-price-in-india | O27: Borderline. Bank offer is conditional and its current validity is unconfirmed
A28: Motorola Edge 70 Pro (ref.) | B28: 12GB+256GB | C28: Amazon India | D28: Not found | E28: 42985 | F28: Not verified | G28: Not verified | H28: Not verified | I28: Not found | J28: Amazon | K28: Listed | L28: Aggregator (91mobiles 14-Oct-2026) | M28: 14-Oct-2026 (IST); via web-search index snapshots | N28: https://www.91mobiles.com/motorola-edge-70-pro-5g-price-in-india | O28: OVER BUDGET. Launch ₹41,999
A29: Motorola Edge 70 Pro (ref.) | B29: 12GB+256GB | C29: Flipkart | D29: Not found | E29: 42999 | F29: Not verified | G29: Not verified | H29: Not verified | I29: Not found | J29: Flipkart | K29: Listed | L29: Aggregator (91mobiles 14-Oct-2026) | M29: 14-Oct-2026 (IST); via web-search index snapshots | N29: https://www.91mobiles.com/motorola-edge-70-pro-5g-price-in-india | O29: Seen at ₹39,999 only during sale events
A31: LOWEST LISTED NON-EXCHANGE PRICE PER MODEL (formula: MINIFS over column E; blank E = not found)
A32: Model | B32: Variant | C32: Lowest listed (₹) | D32: ≤ ₹40,000? | E32: Δ vs baseline 8+256 (₹)
A33: OnePlus Nord CE6 | B33: 8GB+256GB | C33: =_xlfn.MINIFS($E$5:$E$29,$A$5:$A$29,A33,$B$5:$B$29,B33) -> 36999 | D33: =IF(C33<=40000,"Yes","No") -> Yes | E33: =C33-$C$33 -> 0
A34: OPPO K13 Turbo Pro | B34: 12GB+256GB | C34: =_xlfn.MINIFS($E$5:$E$29,$A$5:$A$29,A34,$B$5:$B$29,B34) -> 33999 | D34: =IF(C34<=40000,"Yes","No") -> Yes | E34: =C34-$C$33 -> -3000
A35: iQOO Neo 10R | B35: 12GB+256GB | C35: =_xlfn.MINIFS($E$5:$E$29,$A$5:$A$29,A35,$B$5:$B$29,B35) -> 27990 | D35: =IF(C35<=40000,"Yes","No") -> Yes | E35: =C35-$C$33 -> -9009
A36: realme GT 7T | B36: 12GB+256GB | C36: =_xlfn.MINIFS($E$5:$E$29,$A$5:$A$29,A36,$B$5:$B$29,B36) -> 36990 | D36: =IF(C36<=40000,"Yes","No") -> Yes | E36: =C36-$C$33 -> -9
A37: OnePlus Nord 5 | B37: 12GB+256GB | C37: =_xlfn.MINIFS($E$5:$E$29,$A$5:$A$29,A37,$B$5:$B$29,B37) -> 36999 | D37: =IF(C37<=40000,"Yes","No") -> Yes | E37: =C37-$C$33 -> 0
A38: POCO X8 Pro | B38: 12GB+256GB | C38: =_xlfn.MINIFS($E$5:$E$29,$A$5:$A$29,A38,$B$5:$B$29,B38) -> 39999 | D38: =IF(C38<=40000,"Yes","No") -> Yes | E38: =C38-$C$33 -> 3000
A39: Redmi Note 15 Pro+ | B39: 12GB+512GB | C39: =_xlfn.MINIFS($E$5:$E$29,$A$5:$A$29,A39,$B$5:$B$29,B39) -> 38990 | D39: =IF(C39<=40000,"Yes","No") -> Yes | E39: =C39-$C$33 -> 1991
A40: vivo T5 Pro | B40: 12GB+256GB | C40: =_xlfn.MINIFS($E$5:$E$29,$A$5:$A$29,A40,$B$5:$B$29,B40) -> 39999 | D40: =IF(C40<=40000,"Yes","No") -> Yes | E40: =C40-$C$33 -> 3000
A41: Motorola Edge 70 Pro (ref.) | B41: 12GB+256GB | C41: =_xlfn.MINIFS($E$5:$E$29,$A$5:$A$29,A41,$B$5:$B$29,B41) -> 42985 | D41: =IF(C41<=40000,"Yes","No") -> No | E41: =C41-$C$33 -> 5986
A43: LEGEND
...

Sheet Tech Specs
A1: Full Technical Specifications – side by side
A2: Columns = phones (the baseline is the first column). Values come from official pages and independent spec sheets (GSMArena, 91mobiles, Smartprix). 'Not verified' means it was not confirmed during this research. Brightness labels: typ = typical, HBM = high-brightness mode, peak = small-patch peak.
A4: Specification | B4: Nord CE6 (base) | C4: OPPO K13 Turbo Pro | D4: iQOO Neo 10R | E4: realme GT 7T | F4: OnePlus Nord 5 | G4: POCO X8 Pro | H4: Redmi Note 15 Pro+ | I4: vivo T5 Pro | J4: Moto Edge 70 Pro (ref, >₹40k)
A5: A. PRICE & AVAILABILITY
A6: Variant compared | B6: 8GB+256GB | C6: 12GB+256GB | D6: 12GB+256GB | E6: 12GB+256GB | F6: 12GB+256GB | G6: 12GB+256GB | H6: 12GB+512GB | I6: 12GB+256GB | J6: 12GB+256GB
A7: Regular price used (₹) | B7: =Scorecard!G5 -> 36999 | C7: =Scorecard!G6 -> 33999 | D7: =Scorecard!G7 -> 27990 | E7: =Scorecard!G8 -> 37999 | F7: =Scorecard!G9 -> 36999 | G7: =Scorecard!G10 -> 39999 | H7: =Scorecard!G11 -> 38990 | I7: =Scorecard!G12 -> 39999 | J7: =Scorecard!G13 -> 42985
A8: India launch | B8: May-2026 | C8: Aug-2025 | D8: Mar-2025 | E8: May-2025 | F8: Jul-2025 | G8: Mar-2026 | H8: Jan-2026 | I8: Apr-2026 | J8: Apr-2026
A9: Warranty | B9: 1 yr OnePlus India | C9: 1 yr manufacturer (India) | D9: 1 yr manufacturer (India) | E9: 1 yr manufacturer (India) | F9: 1 yr manufacturer (India) | G9: 1 yr manufacturer (India) | H9: 1 yr manufacturer (India) | I9: 1 yr manufacturer (India) | J9: 1 yr manufacturer (India)
A10: B. PROCESSOR & MEMORY
A11: Chipset | B11: Qualcomm Snapdragon 7s Gen 4 | C11: Qualcomm Snapdragon 8s Gen 4 | D11: Qualcomm Snapdragon 8s Gen 3 | E11: MediaTek Dimensity 8400-Max | F11: Qualcomm Snapdragon 8s Gen 3 | G11: MediaTek Dimensity 8500-Ultra | H11: Qualcomm Snapdragon 7s Gen 4 | I11: Qualcomm Snapdragon 7s Gen 4 | J11: MediaTek Dimensity 8500-Extreme
A12: Physical RAM | B12: 8GB LPDDR4X | C12: 12GB LPDDR5X | D12: 12GB LPDDR5X | E12: 12GB LPDDR5X | F12: 12GB LPDDR5X | G12: 12GB LPDDR5X | H12: 12GB LPDDR4X | I12: 12GB LPDDR4X | J12: 12GB LPDDR5X
A13: Storage / type | B13: 256GB UFS 3.1 (reported) | C13: 256GB UFS 4.0 | D13: 256GB UFS 4.1 | E13: 256GB UFS 4.0 | F13: 256GB UFS 4.0 | G13: 256GB UFS 4.1 | H13: 512GB UFS 2.2 | I13: 256GB UFS 3.1 | J13: 256GB UFS 4.1
A14: Expandable storage | B14: No | C14: No | D14: No | E14: No | F14: No | G14: No | H14: No | I14: No | J14: No
A15: Virtual RAM (ignored for eligibility) | B15: Yes (storage-based) | C15: Yes (storage-based) | D15: Yes (storage-based) | E15: Yes (storage-based) | F15: Yes (storage-based) | G15: Yes (storage-based) | H15: Yes (storage-based) | I15: Yes (storage-based) | J15: Yes (storage-based)
A16: C. DISPLAY
A17: Size / type | B17: 6.78" AMOLED | C17: 6.8" AMOLED | D17: 6.78" AMOLED | E17: 6.8" AMOLED | F17: 6.83" AMOLED | G17: 6.59" AMOLED | H17: 6.83" AMOLED | I17: 6.83" AMOLED | J17: 6.8" P-OLED
A18: Resolution | B18: 1.5K | C18: 1.5K | D18: 1.5K | E18: 1.5K | F18: 1.5K | G18: 1.5K | H18: 1.5K | I18: 1.5K | J18: 1.5K
A19: Refresh rate | B19: 144Hz | C19: 120Hz | D19: 144Hz (games) / 120Hz | E19: 120Hz | F19: 144Hz | G19: 120Hz | H19: 120Hz | I19: 144Hz | J19: 144Hz
A20: Brightness | B20: 800 typ / 1,800 HBM / 3,600 peak | C20: 600 typ / 1,600 HBM | D20: Up to 4,500 peak (claimed) | E20: Up to 6,000 peak (claimed) | F20: 1,800 HBM (claimed) | G20: 3,500 peak claimed; GSMArena measured 797 nits (boost), 3,638 on 10% patch | H20: Not verified | I20: Up to 5,000 local peak (claimed) | J20: Up to 5,200 peak (claimed)
A21: Protection | B21: Not verified | C21: Not verified | D21: Not verified | E21: Not verified | F21: Not verified | G21: Not verified | H21: Gorilla Glass Victus 2 (reported) | I21: Not verified | J21: Gorilla Glass 7i
A22: D. CAMERAS
A23: Main rear | B23: 50MP OV50D40 f/1.8, OIS | C23: 50MP, OIS | D23: 50MP Sony LYT-600, OIS | E23: 50MP Sony IMX896, OIS | F23: 50MP Sony LYT-700 (IMX906), OIS | G23: 50MP, OIS | H23: 200MP, OIS | I23: 50MP Sony IMX882 | J23: 50MP Sony LYTIA, OIS
A24: Ultrawide | B24: None (2MP aux) | C24: None (2MP aux) | D24: 8MP | E24: 8MP | F24: 8MP (116°) | G24: 8MP | H24: 8MP | I24: None (2MP bokeh) | J24: 50MP
A25: Telephoto | B25: No | C25: No | D25: No | E25: No | F25: No | G25: No | H25: No | I25: No | J25: No
A26: Front | B26: 32MP | C26: 16MP | D26: 32MP | E26: 32MP | F26: 50MP (AF) | G26: 20MP | H26: 32MP | I26: 32MP | J26: 50MP
A27: Max video (rear) | B27: Not verified | C27: Not verified | D27: 4K 60fps (reported) | E27: 4K 60fps (reported) | F27: 4K 60fps (reported) | G27: 4K (reported) | H27: 4K 30fps (reported) | I27: 4K (reported) | J27: 4K (reported)
A28: E. BATTERY & CHARGING
A29: Battery | B29: 8,000mAh | C29: 7,000mAh | D29: 6,400mAh | E29: 7,000mAh | F29: 6,800mAh | G29: 6,500mAh | H29: 6,500mAh Si-C | I29: 9,020mAh | J29: 6,500mAh
A30: Wired charging | B30: 80W | C30: 80W | D30: 80W | E30: 120W | F30: 80W | G30: 100W | H30: 100W | I30: 90W | J30: 90W
A31: Measured / claimed charge time | B31: 4→50% ~30 min (Beebom) | C31: Full ~54–55 min (Digit) | D31: Not verified | E31: 50% 15 min / 100% ~40 min (claimed) | F31: Full <40 min (review claim) | G31: 0→100% 41 min (GSMArena) | H31: 20→100% ~38 min (91mobiles) | I31: Not verified | J31: Not verified
A32: Wireless / reverse | B32: No | C32: No | D32: No | E32: No | F32: No | G32: No | H32: No | I32: Not verified | J32: 15W wireless + 10W reverse (region-dependent)
A33: F. SOFTWARE
A34: OS at launch | B34: OxygenOS 16 / Android 16 | C34: ColorOS 15 / Android 15 (now ColorOS 16) | D34: Funtouch 15 / Android 15 (now OriginOS 6) | E34: realme UI 6 / Android 15 | F34: OxygenOS 15 / Android 15 | G34: HyperOS 3 / Android 16 | H34: HyperOS 2 / Android 15 | I34: OriginOS 6 / Android 16 | J34: Hello UI / Android 16
A35: Update commitment | B35: Not officially numbered (reported 2 OS + 4 yr security) | C35: Not officially published | D35: Not verified (forum reports slow updates) | E35: Security to 01-May-2031 (realme official); 3 OS + 4 yr (GT series policy, inferred) | F35: 4 OS + 6 yr security (launch policy) | G35: Not officially confirmed (tracker: support to Mar-2032) | H35: 4 OS + 6 yr security (reported for India) | I35: Not published | J35: 3 OS + 5 yr security
A36: G. CONNECTIVITY & DURABILITY
A37: 5G / dual SIM / NFC | B37: Yes / Yes / Yes | C37: Yes / Yes / Yes | D37: Yes / Yes / Yes | E37: Yes / Yes / Yes | F37: Yes / Yes / Yes | G37: Yes / Yes / Yes | H37: Yes / Yes / Yes | I37: Yes / Yes / Yes | J37: Yes / Yes / Yes
A38: IP rating | B38: IP66/68/69/69K | C38: IP66/68/69 | D38: IP65 | E38: IP66/68/69 | F38: IP65 | G38: IP66/68/69/69K | H38: IP66/68/69 | I38: IP68/69 | J38: IP68/69 + MIL-STD-810H
A39: Weight / thickness | B39: 208–215 g / 8.5 mm | C39: 208 g | D39: 196 g (reported) | E39: ~203 g (reported) | F39: 211 g (reported) | G39: 204 g / 8.2 mm | H39: Not verified | I39: 213 g / 8.25 mm | J39: 183–190 g / ~7.2 mm
A40: Stereo speakers | B40: Yes | C40: Yes | D40: Yes | E40: Yes | F40: Yes | G40: Yes | H40: Yes | I40: Not verified | J40: Yes (Dolby Atmos, reported)
A41: Cooling | B41: Vapour chamber (reported) | C41: Active cooling FAN + vapour chamber | D41: Large vapour chamber | E41: Large vapour chamber | F41: Vapour chamber | G41: Vapour chamber | H41: Not verified | I41: Not verified | J41: Vapour chamber
...

Sheet Processor & Benchmarks
A1: Processor & Benchmark Analysis
A2: Benchmarks come from different sources, versions and test conditions. Read them as performance TIERS. 'Measured' = independent reviewer/lab; 'Crowd avg' = NanoReview/aggregator user runs; 'Claimed' = manufacturer; 'Leak' = pre-launch listing.
A4: Model | B4: Chipset | C4: Process | D4: CPU configuration | E4: GPU | F4: AnTuTu total | G4: AnTuTu version / basis | H4: AnTuTu source | I4: GB6 single | J4: GB6 multi | K4: Geekbench source | L4: 3DMark (Wild Life Extreme) | M4: Status | N4: Perf vs baseline (AnTuTu ×) | O4: Sustained / thermals | P4: Gaming (BGMI / CoD) | Q4: Battery drain under load | R4: Everyday & multitasking | S4: Video | T4: Perf rank (eligible)
A5: OnePlus Nord CE6 (base) | B5: Snapdragon 7s Gen 4 | C5: 4nm | D5: 1×2.7 A720 + 3×2.4 A720 + 4×1.8 A520 | E5: Adreno 810 | F5: 1136269 | G5: v11, average | H5: https://www.mobiledokan.com/review/oneplus-nord-ce6-full-review | I5: 1101 | J5: 3117 | K5: https://www.91mobiles.com/hub/alleged-oneplus-nord-ce-6-geekbench-snapdragon-7s-gen-4/ | L5: Not found | M5: Crowd avg (AnTuTu) / Leak (GB) | N5: =IF(ISNUMBER(F5),F5/$F$5,"n/a") -> 1 | O5: Mild warmth; no throttling complaints in the reviews found | P5: BGMI runs well, per reviewers (Smartprix/Beebom). Not a high-FPS phone | Q5: Low drain: 8,000mAh. Idle ~0.75%/hr (Beebom) | R5: Smooth for daily use; 8GB RAM limits heavy multitasking | S5: No ultrawide; basic video | T5: =IF(Scorecard!T5="Yes",COUNTIFS(Scorecard!$T$5:$T$13,"Yes",Scorecard!$H$5:$H$13,">"&Scorecard!H5)+1,"Excluded") -> Excluded
A6: OPPO K13 Turbo Pro | B6: Snapdragon 8s Gen 4 | C6: 4nm | D6: 1×3.21 X4 + 3×3.0 A720 + 2×2.8 A720 + 2×2.0 A720 | E6: Adreno 825 | F6: 2029394 | G6: v10, single review run (Digit reports 'over 2M') | H6: https://www.digit.in/reviews/mobile-phones/oppo-k13-turbo-pro-review-power-doesnt-quit-cooling-fan-or-not.html | I6: 2152 | J6: 6744 | K6: https://www.digit.in/reviews/mobile-phones/oppo-k13-turbo-pro-review-power-doesnt-quit-cooling-fan-or-not.html | L6: SD 8s Gen 4 class: ~3,500–4,470 (POCO F7, Gizmochina) | M6: Measured | N6: =IF(ISNUMBER(F6),F6/$F$5,"n/a") -> 1.7860155 | O6: Built-in fan. 91mobiles: switching the fan off cuts frame rates and thermals worsen. Digit: performance stays consistent | P6: Best sustained gaming in the eligible set | Q6: PCMark >17 h screen-on (Digit). 1.5 days moderate use | R6: Flagship-class | S6: Not verified | T6: =IF(Scorecard!T6="Yes",COUNTIFS(Scorecard!$T$5:$T$13,"Yes",Scorecard!$H$5:$H$13,">"&Scorecard!H6)+1,"Excluded") -> 1
A7: iQOO Neo 10R | B7: Snapdragon 8s Gen 3 | C7: 4nm | D7: 1×3.0 X4 + 4×2.8 A720 + 3×2.0 A520 | E7: Adreno 735 | F7: 1527083 | G7: v10, review run (range 1.48–1.79M) | H7: https://www.91mobiles.com/hub/iqoo-neo-10r-review/ | I7: 1882 | J7: 4598 | K7: https://nanoreview.net/en/phone/vivo-iqoo-neo-7-pro | L7: Not found | M7: Measured (AnTuTu) / Crowd avg (GB) | N7: =IF(ISNUMBER(F7),F7/$F$5,"n/a") -> 1.343945 | O7: Good. Gaming-focused tuning | P7: BGMI/CoD frame rates similar to POCO X7 Pro (91mobiles). 144Hz in supported games | Q7: PCMark >16 h (review) | R7: Fast | S7: 4K60 (reported) | T7: =IF(Scorecard!T7="Yes",COUNTIFS(Scorecard!$T$5:$T$13,"Yes",Scorecard!$H$5:$H$13,">"&Scorecard!H7)+1,"Excluded") -> 4
A8: realme GT 7T | B8: Dimensity 8400-Max | C8: 4nm | D8: 1×3.25 A725 + 3×3.0 A725 + 4×2.1 A725 | E8: Mali-G720 MC7 | F8: 1780000 | G8: Manufacturer claim 'over 1.78M' (independent runs vary 1.6M–2.2M) | H8: https://www.realme.com/in/realme-gt-7t-5g | I8: 1660 | J8: 6497 | K8: https://www.mysmartprice.com/performance-test/realme-gt-7t-619909 | L8: Not found | M8: Claimed (AnTuTu) / Measured (GB) | N8: =IF(ISNUMBER(F8),F8/$F$5,"n/a") -> 1.5665305 | O8: Large vapour chamber. No major throttling reports found | P8: Strong high-FPS gaming | Q8: Good: 7,000mAh | R8: Fast | S8: 4K60 (reported) | T8: =IF(Scorecard!T8="Yes",COUNTIFS(Scorecard!$T$5:$T$13,"Yes",Scorecard!$H$5:$H$13,">"&Scorecard!H8)+1,"Excluded") -> 3
A9: OnePlus Nord 5 | B9: Snapdragon 8s Gen 3 | C9: 4nm | D9: 1×3.0 X4 + 4×2.8 A720 + 3×2.0 A520 | E9: Adreno 735 | F9: 1455406 | G9: v10, review run (other run 1,481,616) | H9: https://www.91mobiles.com/reviews/oneplus-nord-5-review/ | I9: 1992 | J9: 5079 | K9: https://www.mysmartprice.com/mobile/oneplus-nord-5-msp22894/benchmark-scores | L9: Not found | M9: Measured | N9: =IF(ISNUMBER(F9),F9/$F$5,"n/a") -> 1.280864 | O9: Good (vapour chamber) | P9: Strong: 144Hz | Q9: 2 days moderate use (review) | R9: Fast | S9: 4K60 (reported) | T9: =IF(Scorecard!T9="Yes",COUNTIFS(Scorecard!$T$5:$T$13,"Yes",Scorecard!$H$5:$H$13,">"&Scorecard!H9)+1,"Excluded") -> 4
A10: POCO X8 Pro | B10: Dimensity 8500-Ultra | C10: 4nm | D10: 1×3.4 A725 + 3×3.2 A725 + 4×2.2 A725 (reported) | E10: Mali-G720 MC8 | F10: 2090000 | G10: v11 crowd avg ~2.09M (GSMArena own run 1.66M) | H10: https://nanoreview.net/en/phone/xiaomi-poco-x8-pro | I10: 1751 | J10: 6824 | K10: https://nanoreview.net/en/phone/xiaomi-poco-x8-pro | L10: ~3,056–4,162 low/high loop (Gizmochina) | M10: Crowd avg / Measured | N10: =IF(ISNUMBER(F10),F10/$F$5,"n/a") -> 1.8393532 | O10: Near-flagship (GSMArena). Gets hot while charging | P10: Strong: D8500 ≈ SD 8s Gen 4 in GPU tests | Q10: GSMArena Active Use 16:52 h. Beebom ~7 h SoT | R10: Fast | S10: 4K (reported) | T10: =IF(Scorecard!T10="Yes",COUNTIFS(Scorecard!$T$5:$T$13,"Yes",Scorecard!$H$5:$H$13,">"&Scorecard!H10)+1,"Excluded") -> 1
A11: Redmi Note 15 Pro+ | B11: Snapdragon 7s Gen 4 | C11: 4nm | D11: 1×2.7 A720 + 3×2.4 A720 + 4×1.8 A520 | E11: Adreno 810 | F11: 1047274 | G11: MySmartPrice lab (version not stated) | H11: https://www.mysmartprice.com/performance-test/xiaomi-redmi-note-15-pro-plus-23455 | I11: 1266 | J11: 3154 | K11: https://www.mysmartprice.com/performance-test/xiaomi-redmi-note-15-pro-plus-23455 | L11: Not found | M11: Measured | N11: =IF(ISNUMBER(F11),F11/$F$5,"n/a") -> 0.92167788 | O11: OK. Smartprix reports occasional lag | P11: Casual/medium settings | Q11: Good: 6,500mAh Si-C | R11: Decent, not fast (Smartprix). UFS 2.2 slows app installs | S11: 200MP stills. Video not standout | T11: =IF(Scorecard!T11="Yes",COUNTIFS(Scorecard!$T$5:$T$13,"Yes",Scorecard!$H$5:$H$13,">"&Scorecard!H11)+1,"Excluded") -> 6
A12: vivo T5 Pro | B12: Snapdragon 7s Gen 4 | C12: 4nm | D12: 1×2.7 A720 + 3×2.4 A720 + 4×1.8 A520 | E12: Adreno 810 | F12: 1180000 | G12: Digit review (vivo claims 1.2M) | H12: https://www.digit.in/reviews/mobile-phones/vivo-t5-pro-review-9020mah-big-battery-for-rs-30000-but-what-is-the-catch.html | I12: 1245 | J12: 3196 | K12: https://www.digit.in/reviews/mobile-phones/vivo-t5-pro-review-9020mah-big-battery-for-rs-30000-but-what-is-the-catch.html | L12: Not found | M12: Measured | N12: =IF(ISNUMBER(F12),F12/$F$5,"n/a") -> 1.0384865 | O12: Same tier as baseline | P12: BGMI fine at balanced settings | Q12: Excellent: ~2 days (9,020mAh) | R12: Smooth | S12: Weak low-light video (reviews) | T12: =IF(Scorecard!T12="Yes",COUNTIFS(Scorecard!$T$5:$T$13,"Yes",Scorecard!$H$5:$H$13,">"&Scorecard!H12)+1,"Excluded") -> 6
A13: Moto Edge 70 Pro (ref, >₹40k) | B13: Dimensity 8500-Extreme | C13: 4nm | D13: 1×3.4 A725 + 3×3.2 A725 + 4×2.2 A725 (reported) | E13: Mali-G720 MC8 | F13: 2170000 | G13: Review run (other ~2.19M) | H13: https://www.digit.in/reviews/mobile-phones/motorola-edge-70-pro-review-one-of-the-most-complete-phones-you-can-buy-but.html | I13: Not found | J13: Not found | K13: Not found | L13: Not found | M13: Measured | N13: =IF(ISNUMBER(F13),F13/$F$5,"n/a") -> 1.909759 | O13: Inconsistent thermal management (reviewers) | P13: Strong | Q13: NanoReview: 14:43 h web, 23:48 h video | R13: Fast | S13: Good. Strong ultrawide | T13: =IF(Scorecard!T13="Yes",COUNTIFS(Scorecard!$T$5:$T$13,"Yes",Scorecard!$H$5:$H$13,">"&Scorecard!H13)+1,"Excluded") -> Excluded
A15: Real-world ranking (benchmarks + sustained behaviour): 1) OPPO K13 Turbo Pro (SD 8s Gen 4 + fan) ≈ 2) POCO X8 Pro (D8500-Ultra) > 3) realme GT 7T (D8400-Max) > 4) OnePlus Nord 5 ≈ iQOO Neo 10R (SD 8s Gen 3) >> vivo T5 Pro ≈ Nord CE6 ≈ Redmi Note 15 Pro+ (SD 7s Gen 4). Max-highlights in F/I/J exclude the baseline row and the over-budget Moto row.
A16: 3DMark Wild Life Extreme figures were found only for the SD 8s Gen 4 vs Dimensity 8500 comparison (Gizmochina, NanoReview, Beebom). Sources disagree on which chip leads, so they are treated as equal tier. Source: https://www.gizmochina.com/2026/06/06/snapdragon-8s-gen-4-vs-dimensity-8500-ultra-benchmark-score-spec-sheet-and-more/
A17: The Redmi Note 15 Pro+ uses the same SoC as the baseline but measured ~8% lower on AnTuTu. Its slower LPDDR4X RAM and UFS 2.2 storage are the likely cause.
A18: CPU core layouts follow Qualcomm/MediaTek public spec sheets as reported by the spec aggregators. They were not re-fetched from the vendors' sites in this session.
A20: LEGEND
A21: Verified (official / retailer / independent test)
A22: Estimate, aggregator snapshot or conflicting sources
A23: Not found / unavailable / not accessible
A24: Conditional offer (bank / exchange / coupon)
A25: Category winner / qualifies
A26: Fails a mandatory rule (price > ₹40,000, RAM < 12GB, CPU below baseline)

Sheet Ratings & Reviews
A1: Customer Ratings & Independent Reviews
A2: Customer ratings are kept separate from professional scores. Ratings came through aggregators (MySmartPrice, 91mobiles, deal sites scraping Amazon), because retailer pages could not be opened directly. Counts can combine variants.
A4: Model | B4: Customer rating (/5) | C4: No. of ratings | D4: Platform | E4: Date checked | F4: Rating source link | G4: Rating status | H4: Expert score / verdict | I4: Expert source | J4: Praised | K4: Complaints | L4: Camera feedback | M4: Battery / charging feedback | N4: Gaming / heat feedback | O4: Software feedback | P4: Build feedback
A5: OnePlus Nord CE6 (base) | B5: 4.3 | C5: 2136 | D5: Amazon (via deal-site scrape); MSP 256GB: 1,312 | E5: 14-Oct-2026 (IST); via web-search index snapshots | F5: https://www.mysmartprice.com/mobile/oneplus-nord-ce-6-5g-256gb-msp620884 | G5: Aggregator | H5: No numeric score | I5: https://www.smartprix.com/bytes/oneplus-nord-ce6-review-with-pros-and-cons/ | J5: Battery, IP69K durability, display, selfie | K5: Confusing camera choices (no ultrawide), price hikes, 8GB only, fewer OS upgrades | L5: Main camera OK in daylight; no ultrawide | M5: Excellent, 2-day battery | N5: Handles BGMI well | O5: Clean OxygenOS 16. Update promise reduced | P5: Solid, IP69K
A6: OPPO K13 Turbo Pro | B6: 4.4 | C6: 814 | D6: MySmartPrice aggregate (12GB variant) | E6: 14-Oct-2026 (IST); via web-search index snapshots | F6: https://www.mysmartprice.com/mobile/oppo-k13-turbo-pro-12gb-msp620188 | G6: Aggregator | H6: Positive (Digit: 'power doesn't quit') | I6: https://www.digit.in/reviews/mobile-phones/oppo-k13-turbo-pro-review-power-doesnt-quit-cooling-fan-or-not.html | J6: Raw performance, cooling fan, battery | K6: Limited update policy, basic camera, stock availability | L6: Average; no ultrawide | M6: PCMark >17 h. 80W | N6: Stays cool under load | O6: ColorOS 16 rolled out; long-term policy unclear | P6: IP69 despite fan; 208 g
A7: iQOO Neo 10R | B7: 4.5 | C7: 14200 | D7: MySmartPrice aggregate (Digit voters: 3.7 from 306) | E7: 14-Oct-2026 (IST); via web-search index snapshots | F7: https://www.mysmartprice.com/mobile/iqoo-neo-10r-msp619551 | G7: Aggregator | H7: Positive (Digit: 'the gaming phone you were waiting for') | I7: https://www.digit.in/reviews/mobile-phones/iqoo-neo-10r-review-the-gaming-phone-you-were-waiting-for.html | J7: Performance per rupee, 144Hz, battery | K7: IP65 only, slow update rollouts (forum) | L7: Good main camera, average ultrawide | M7: PCMark >16 h | N7: Strong gaming | O7: Now on OriginOS 6. Updates reportedly slow | P7: Light, 196 g
A8: realme GT 7T | B8: 4.5 | C8: Not found | D8: 91mobiles aggregate (12GB). Count not shown | E8: 14-Oct-2026 (IST); via web-search index snapshots | F8: https://www.91mobiles.com/realme-gt-7t-price-in-india | G8: Aggregator (no count) | H8: NanoReview: camera 73, battery 90 | I8: https://nanoreview.net/en/phone/realme-gt-7t | J8: Battery + 120W charging, bright display, performance | K8: Camera merely good; low-light average | L8: Decent daylight, average night | M8: Excellent, 7,000mAh / 120W | N8: No major heat reports found | O8: realme UI. Some bloat | P8: IP69
A9: OnePlus Nord 5 | B9: Not found | C9: Not found | D9: Not found | E9: 14-Oct-2026 (IST); via web-search index snapshots | F9: https://www.smartprix.com/mobiles/oneplus-nord-5-12gb-ram-256gb-ppd1b9svl1s7 | G9: Not found | H9: Positive (Fonearena: 'complete mid-range package') | I9: https://www.fonearena.com/blog/458245/oneplus-nord-5-review.html | J9: Balanced; main + selfie camera; 144Hz | K9: Weak ultrawide; chip a generation old; stock | L9: Reliable main, weak ultrawide | M9: 2 days moderate use | N9: Good | O9: Clean OxygenOS. 4 OS + 6 yr | P9: IP65
A10: POCO X8 Pro | B10: 4.3 | C10: 2816 | D10: Flipkart (8GB/256GB listing) | E10: 14-Oct-2026 (IST); via web-search index snapshots | F10: https://www.flipkart.com/poco-x8-pro-white-256-gb/p/itmaa692ca8a3b36 | G10: Retailer snapshot | H10: Gadreview battery 9.5/10, camera 7.5/10 | I10: https://www.gsmarena.com/poco_x8_pro-review-2946p6.php | J10: Chip, battery life, fast charging, display | K10: Average cameras; HyperOS ads; heats while charging | L10: 'Average at best' (Beebom) | M10: 16:52 h Active Use (GSMArena) | N10: Near-flagship. Warm when charging | O10: HyperOS 3. Touch-fix updates delivered | P10: IP69K, 204 g
A11: Redmi Note 15 Pro+ | B11: Not found | C11: Not found | D11: Not found | E11: 14-Oct-2026 (IST); via web-search index snapshots | F11: https://www.91mobiles.com/xiaomi-redmi-note-15-pro-plus-price-in-india | G11: Not found | H11: 91mobiles 8.1/10 | I11: https://www.91mobiles.com/reviews/redmi-note-15-pro-plus-review/ | J11: 200MP daylight photos, battery, durability, display | K11: Android 15 at launch, ads/bloat, occasional lag, UFS 2.2 | L11: Excellent daylight; weaker portraits/low light/ultrawide | M11: Lasts to next morning for heavy users; 38 min charge | N11: Medium | O11: HyperOS ads (Smartprix) | P11: IP66/68/69
A12: vivo T5 Pro | B12: Not found | C12: Not found | D12: Not found | E12: 14-Oct-2026 (IST); via web-search index snapshots | F12: https://www.91mobiles.com/vivo-t5-pro-price-in-india | G12: Not found | H12: Beebom 8.5/10; Editorji 8.5/10 | I12: https://gadgets.beebom.com/reviews/vivo-t5-pro-review | J12: Massive battery, bright 144Hz display | K12: Chip a sidegrade vs T4 Pro; no ultrawide; weak low light | L12: Daylight OK, low light weak | M12: Best here: ~2 days | N12: Fine | O12: OriginOS 6. Policy unpublished | P12: IP68/69, 213 g
A13: Moto Edge 70 Pro (ref, >₹40k) | B13: 4.2 | C13: 198 | D13: Flipkart (Edge 70 Pro+ listing – different variant) | E13: 14-Oct-2026 (IST); via web-search index snapshots | F13: https://www.flipkart.com/motorola-edge-70-pro/p/itm70caeee0ca941 | G13: Retailer snapshot (variant mismatch) | H13: Digit: 'one of the most complete phones you can buy, but…' | I13: https://www.digit.in/reviews/mobile-phones/motorola-edge-70-pro-review-one-of-the-most-complete-phones-you-can-buy-but.html | J13: Ultrawide, display, slim 7.2mm build | K13: Inconsistent thermals; skin tones | L13: Best ultrawide in group | M13: Good | N13: Thermal inconsistency | O13: Near-stock Hello UI | P13: IP68/69 + MIL-STD
A15: Confidence rule: a 4.5 from ~14K ratings (Neo 10R) outweighs a 4.5 with no count (GT 7T). Phones without a found rating count score only 2/5 in 'Ratings & reliability'. High early ratings are not taken as proof of long-term reliability.
A17: LEGEND
A18: Verified (official / retailer / independent test)
A19: Estimate, aggregator snapshot or conflicting sources
A20: Not found / unavailable / not accessible
A21: Conditional offer (bank / exchange / coupon)
A22: Category winner / qualifies
A23: Fails a mandatory rule (price > ₹40,000, RAM < 12GB, CPU below baseline)

Sheet Scorecard
A1: Weighted Scorecard (out of 100)
A2: Research date 14-Oct-2026. Edit the blue category scores (cols H–O); totals, eligibility, ranks and winners recalculate. Eligibility is separate from score: regular price ≤ ₹40,000 (no bank/exchange), physical RAM ≥ 12GB, CPU matches/exceeds baseline.
A4: Key | B4: Model | C4: Variant | D4: Release year | E4: Chipset | F4: Physical RAM (GB) | G4: Regular price (₹) | H4: Processor & sustained (25) | I4: Display (15) | J4: Camera (15) | K4: Battery & charging (15) | L4: Software & UX (10) | M4: Build & durability (5) | N4: Ratings & reliability (5) | O4: Value for money (10) | P4: TOTAL (100) | Q4: Price ≤ ₹40k? | R4: RAM ≥ 12GB? | S4: CPU ≥ baseline? | T4: ELIGIBLE? | U4: Overall rank (eligible) | V4: Δ price vs baseline (₹) | W4: Best retailer link | X4: Score justification | Z4: helper_P | AA4: helper_H | AB4: helper_J | AC4: helper_K | AD4: helper_I | AE4: helper_L | AF4: helper_M | AG4: helper_N | AH4: helper_O
A5: CE6 | B5: OnePlus Nord CE6 (BASELINE) | C5: 8GB + 256GB | D5: 2026 | E5: Qualcomm Snapdragon 7s Gen 4 | F5: 8 | G5: 36999 | H5: 15 | I5: 11 | J5: 9 | K5: 14 | L5: 6 | M5: 5 | N5: 4 | O5: 6 | P5: =SUM(H5:O5) -> 70 | Q5: =IF(G5<=40000,"Yes","No") -> Yes | R5: =IF(F5>=12,"Yes","No") -> No | S5: Baseline | T5: =IF(AND(Q5="Yes",R5="Yes",S5="Yes"),"Yes","No") -> No | U5: =IF(T5="Yes",COUNTIFS($T$5:$T$13,"Yes",$P$5:$P$13,">"&P5)+1,"Excluded") -> Excluded | V5: =G5-$G$5 -> 0 | W5: =HYPERLINK("https://www.amazon.in/OnePlus-Snapdragon-Segments-Fastest-Response/dp/B0GWLHVJRH","Open listing / source") -> Open listing / source | X5: Huge 8,000mAh battery and IP69K, but mid-tier chip (AnTuTu ~1.14M), single useful rear camera (no ultrawide), only 8GB RAM, and unclear update promise (reported 2 OS upgrades). | Z5: =IF($T5="Yes",P5+(100-ROW())/1000,-1) -> -1 | AA5: =IF($T5="Yes",H5+(100-ROW())/1000,-1) -> -1 | AB5: =IF($T5="Yes",J5+(100-ROW())/1000,-1) -> -1 | AC5: =IF($T5="Yes",K5+(100-ROW())/1000,-1) -> -1 | AD5: =IF($T5="Yes",I5+(100-ROW())/1000,-1) -> -1 | AE5: =IF($T5="Yes",L5+(100-ROW())/1000,-1) -> -1 | AF5: =IF($T5="Yes",M5+(100-ROW())/1000,-1) -> -1 | AG5: =IF($T5="Yes",N5+(100-ROW())/1000,-1) -> -1 | AH5: =IF($T5="Yes",O5+(100-ROW())/1000,-1) -> -1
A6: K13TP | B6: OPPO K13 Turbo Pro 5G | C6: 12GB + 256GB | D6: 2025 | E6: Qualcomm Snapdragon 8s Gen 4 | F6: 12 | G6: 33999 | H6: 24 | I6: 11 | J6: 9 | K6: 12 | L6: 5 | M6: 4 | N6: 4 | O6: 9 | P6: =SUM(H6:O6) -> 78 | Q6: =IF(G6<=40000,"Yes","No") -> Yes | R6: =IF(F6>=12,"Yes","No") -> Yes | S6: Yes | T6: =IF(AND(Q6="Yes",R6="Yes",S6="Yes"),"Yes","No") -> Yes | U6: =IF(T6="Yes",COUNTIFS($T$5:$T$13,"Yes",$P$5:$P$13,">"&P6)+1,"Excluded") -> 3 | V6: =G6-$G$5 -> -3000 | W6: =HYPERLINK("https://www.flipkart.com/oppo-k13-turbo-pro-5g-silver-knight-256-gb/p/itmeefeb718f01fe","Open listing / source") -> Open listing / source | X6: Top performance (AnTuTu ~2.0M, GB6 2152/6744) plus an active cooling fan for sustained gaming; lowest price of the flagship-chip group. Loses points for basic camera (no ultrawide), 1600-nit HBM screen, unclear update policy and stock flicker. | Z6: =IF($T6="Yes",P6+(100-ROW())/1000,-1) -> 78.094 | AA6: =IF($T6="Yes",H6+(100-ROW())/1000,-1) -> 24.094 | AB6: =IF($T6="Yes",J6+(100-ROW())/1000,-1) -> 9.094 | AC6: =IF($T6="Yes",K6+(100-ROW())/1000,-1) -> 12.094 | AD6: =IF($T6="Yes",I6+(100-ROW())/1000,-1) -> 11.094 | AE6: =IF($T6="Yes",L6+(100-ROW())/1000,-1) -> 5.094 | AF6: =IF($T6="Yes",M6+(100-ROW())/1000,-1) -> 4.094 | AG6: =IF($T6="Yes",N6+(100-ROW())/1000,-1) -> 4.094 | AH6: =IF($T6="Yes",O6+(100-ROW())/1000,-1) -> 9.094
A7: NEO10R | B7: iQOO Neo 10R 5G | C7: 12GB + 256GB | D7: 2025 | E7: Qualcomm Snapdragon 8s Gen 3 | F7: 12 | G7: 27990 | H7: 20 | I7: 12 | J7: 10 | K7: 11 | L7: 6 | M7: 3 | N7: 5 | O7: 10 | P7: =SUM(H7:O7) -> 77 | Q7: =IF(G7<=40000,"Yes","No") -> Yes | R7: =IF(F7>=12,"Yes","No") -> Yes | S7: Yes | T7: =IF(AND(Q7="Yes",R7="Yes",S7="Yes"),"Yes","No") -> Yes | U7: =IF(T7="Yes",COUNTIFS($T$5:$T$13,"Yes",$P$5:$P$13,">"&P7)+1,"Excluded") -> 4 | V7: =G7-$G$5 -> -9009 | W7: =HYPERLINK("https://www.91mobiles.com/iqoo-neo-10r-price-in-india","Open listing / source") -> Open listing / source | X7: SD 8s Gen 3 (AnTuTu ~1.5M) and 144Hz screen at ~₹28–31k; best rating base (4.5 from ~14K ratings, aggregated). IP65 only, 6,400mAh is now merely average, older 2025 model. | Z7: =IF($T7="Yes",P7+(100-ROW())/1000,-1) -> 77.093 | AA7: =IF($T7="Yes",H7+(100-ROW())/1000,-1) -> 20.093 | AB7: =IF($T7="Yes",J7+(100-ROW())/1000,-1) -> 10.093 | AC7: =IF($T7="Yes",K7+(100-ROW())/1000,-1) -> 11.093 | AD7: =IF($T7="Yes",I7+(100-ROW())/1000,-1) -> 12.093 | AE7: =IF($T7="Yes",L7+(100-ROW())/1000,-1) -> 6.093 | AF7: =IF($T7="Yes",M7+(100-ROW())/1000,-1) -> 3.093 | AG7: =IF($T7="Yes",N7+(100-ROW())/1000,-1) -> 5.093 | AH7: =IF($T7="Yes",O7+(100-ROW())/1000,-1) -> 10.093
A8: GT7T | B8: realme GT 7T 5G | C8: 12GB + 256GB | D8: 2025 | E8: MediaTek Dimensity 8400-Max | F8: 12 | G8: 37999 | H8: 22 | I8: 13 | J8: 10 | K8: 13 | L8: 7 | M8: 4 | N8: 4 | O8: 8 | P8: =SUM(H8:O8) -> 81 | Q8: =IF(G8<=40000,"Yes","No") -> Yes | R8: =IF(F8>=12,"Yes","No") -> Yes | S8: Yes | T8: =IF(AND(Q8="Yes",R8="Yes",S8="Yes"),"Yes","No") -> Yes | U8: =IF(T8="Yes",COUNTIFS($T$5:$T$13,"Yes",$P$5:$P$13,">"&P8)+1,"Excluded") -> 1 | V8: =G8-$G$5 -> 1000 | W8: =HYPERLINK("https://www.reliancedigital.in/product/realme-gt-7t-5g-256-gb-12-gb-ram-blue-mobile-phone-mbgan1-9247285","Open listing / source") -> Open listing / source | X8: Strong D8400-Max (GB6 1660/6497), 7,000mAh + 120W (fastest charging here), 6,000-nit 1.5K panel, IP69, realme security support to May-2031. Camera good, not great. | Z8: =IF($T8="Yes",P8+(100-ROW())/1000,-1) -> 81.092 | AA8: =IF($T8="Yes",H8+(100-ROW())/1000,-1) -> 22.092 | AB8: =IF($T8="Yes",J8+(100-ROW())/1000,-1) -> 10.092 | AC8: =IF($T8="Yes",K8+(100-ROW())/1000,-1) -> 13.092 | AD8: =IF($T8="Yes",I8+(100-ROW())/1000,-1) -> 13.092 | AE8: =IF($T8="Yes",L8+(100-ROW())/1000,-1) -> 7.092 | AF8: =IF($T8="Yes",M8+(100-ROW())/1000,-1) -> 4.092 | AG8: =IF($T8="Yes",N8+(100-ROW())/1000,-1) -> 4.092 | AH8: =IF($T8="Yes",O8+(100-ROW())/1000,-1) -> 8.092
A9: NORD5 | B9: OnePlus Nord 5 | C9: 12GB + 256GB | D9: 2025 | E9: Qualcomm Snapdragon 8s Gen 3 | F9: 12 | G9: 36999 | H9: 20 | I9: 12 | J9: 11 | K9: 12 | L9: 7 | M9: 3 | N9: 2 | O9: 7 | P9: =SUM(H9:O9) -> 74 | Q9: =IF(G9<=40000,"Yes","No") -> Yes | R9: =IF(F9>=12,"Yes","No") -> Yes | S9: Yes | T9: =IF(AND(Q9="Yes",R9="Yes",S9="Yes"),"Yes","No") -> Yes | U9: =IF(T9="Yes",COUNTIFS($T$5:$T$13,"Yes",$P$5:$P$13,">"&P9)+1,"Excluded") -> 5 | V9: =G9-$G$5 -> 0 | W9: =HYPERLINK("https://www.bajajfinserv.in/oneplus-nord-5-price-in-india","Open listing / source") -> Open listing / source | X9: SD 8s Gen 3, best camera pairing in the eligible set (Sony LYT-700 OIS + 50MP AF selfie), 4 OS + 6 yr security promise. Docked for stock risk, IP65, no verified rating count. | Z9: =IF($T9="Yes",P9+(100-ROW())/1000,-1) -> 74.091 | AA9: =IF($T9="Yes",H9+(100-ROW())/1000,-1) -> 20.091 | AB9: =IF($T9="Yes",J9+(100-ROW())/1000,-1) -> 11.091 | AC9: =IF($T9="Yes",K9+(100-ROW())/1000,-1) -> 12.091 | AD9: =IF($T9="Yes",I9+(100-ROW())/1000,-1) -> 12.091 | AE9: =IF($T9="Yes",L9+(100-ROW())/1000,-1) -> 7.091 | AF9: =IF($T9="Yes",M9+(100-ROW())/1000,-1) -> 3.091 | AG9: =IF($T9="Yes",N9+(100-ROW())/1000,-1) -> 2.091 | AH9: =IF($T9="Yes",O9+(100-ROW())/1000,-1) -> 7.091
A10: X8PRO | B10: POCO X8 Pro 5G | C10: 12GB + 256GB | D10: 2026 | E10: MediaTek Dimensity 8500-Ultra | F10: 12 | G10: 39999 | H10: 24 | I10: 12 | J10: 9 | K10: 12 | L10: 6 | M10: 5 | N10: 4 | O10: 7 | P10: =SUM(H10:O10) -> 79 | Q10: =IF(G10<=40000,"Yes","No") -> Yes | R10: =IF(F10>=12,"Yes","No") -> Yes | S10: Yes | T10: =IF(AND(Q10="Yes",R10="Yes",S10="Yes"),"Yes","No") -> Yes | U10: =IF(T10="Yes",COUNTIFS($T$5:$T$13,"Yes",$P$5:$P$13,">"&P10)+1,"Excluded") -> 2 | V10: =G10-$G$5 -> 3000 | W10: =HYPERLINK("https://www.smartprix.com/mobiles/poco-x8-pro-5g-12gb-ram-256gb-ppd15mvem8mu","Open listing / source") -> Open listing / source | X10: Newest flagship-class chip (D8500-Ultra, AnTuTu ~1.7–2.1M), GSMArena 16:52h Active Use, 100W (0–100% 41 min), IP69K. Camera average; update policy not officially confirmed; price borderline. | Z10: =IF($T10="Yes",P10+(100-ROW())/1000,-1) -> 79.09 | AA10: =IF($T10="Yes",H10+(100-ROW())/1000,-1) -> 24.09 | AB10: =IF($T10="Yes",J10+(100-ROW())/1000,-1) -> 9.09 | AC10: =IF($T10="Yes",K10+(100-ROW())/1000,-1) -> 12.09 | AD10: =IF($T10="Yes",I10+(100-ROW())/1000,-1) -> 12.09 | AE10: =IF($T10="Yes",L10+(100-ROW())/1000,-1) -> 6.09 | AF10: =IF($T10="Yes",M10+(100-ROW())/1000,-1) -> 5.09 | AG10: =IF($T10="Yes",N10+(100-ROW())/1000,-1) -> 4.09 | AH10: =IF($T10="Yes",O10+(100-ROW())/1000,-1) -> 7.09
A11: RN15PP | B11: Redmi Note 15 Pro+ 5G | C11: 12GB + 512GB | D11: 2026 | E11: Qualcomm Snapdragon 7s Gen 4 | F11: 12 | G11: 38990 | H11: 15 | I11: 12 | J11: 12 | K11: 12 | L11: 8 | M11: 5 | N11: 2 | O11: 7 | P11: =SUM(H11:O11) -> 73 | Q11: =IF(G11<=40000,"Yes","No") -> Yes | R11: =IF(F11>=12,"Yes","No") -> Yes | S11: Yes | T11: =IF(AND(Q11="Yes",R11="Yes",S11="Yes"),"Yes","No") -> Yes | U11: =IF(T11="Yes",COUNTIFS($T$5:$T$13,"Yes",$P$5:$P$13,">"&P11)+1,"Excluded") -> 6 | V11: =G11-$G$5 -> 1991 | W11: =HYPERLINK("https://www.flipkart.com/redmi-note-15-pro-5g-carbon-black-512-gb/p/itm3174106e5bf60","Open listing / source") -> Open listing / source | X11: Same chip as baseline (no CPU gain), slow LPDDR4X/UFS 2.2; but 200MP OIS main camera, 512GB, IP66/68/69, 4 OS + 6 yr policy. HyperOS ads/bloat reported. | Z11: =IF($T11="Yes",P11+(100-ROW())/1000,-1) -> 73.089 | AA11: =IF($T11="Yes",H11+(100-ROW())/1000,-1) -> 15.089 | AB11: =IF($T11="Yes",J11+(100-ROW())/1000,-1) -> 12.089 | AC11: =IF($T11="Yes",K11+(100-ROW())/1000,-1) -> 12.089 | AD11: =IF($T11="Yes",I11+(100-ROW())/1000,-1) -> 12.089 | AE11: =IF($T11="Yes",L11+(100-ROW())/1000,-1) -> 8.089 | AF11: =IF($T11="Yes",M11+(100-ROW())/1000,-1) -> 5.089 | AG11: =IF($T11="Yes",N11+(100-ROW())/1000,-1) -> 2.089 | AH11: =IF($T11="Yes",O11+(100-ROW())/1000,-1) -> 7.089
A12: T5PRO | B12: vivo T5 Pro 5G | C12: 12GB + 256GB | D12: 2026 | E12: Qualcomm Snapdragon 7s Gen 4 | F12: 12 | G12: 39999 | H12: 15 | I12: 12 | J12: 8 | K12: 15 | L12: 5 | M12: 5 | N12: 2 | O12: 6 | P12: =SUM(H12:O12) -> 68 | Q12: =IF(G12<=40000,"Yes","No") -> Yes | R12: =IF(F12>=12,"Yes","No") -> Yes | S12: Yes | T12: =IF(AND(Q12="Yes",R12="Yes",S12="Yes"),"Yes","No") -> Yes | U12: =IF(T12="Yes",COUNTIFS($T$5:$T$13,"Yes",$P$5:$P$13,">"&P12)+1,"Excluded") -> 7 | V12: =G12-$G$5 -> 3000 | W12: =HYPERLINK("https://www.91mobiles.com/vivo-t5-pro-price-in-india","Open listing / source") -> Open listing / source | X12: Biggest battery (9,020mAh) and bright 144Hz panel, but same chip as baseline, 50MP+2MP camera with no ultrawide, update policy not published. Price borderline. | Z12: =IF($T12="Yes",P12+(100-ROW())/1000,-1) -> 68.088 | AA12: =IF($T12="Yes",H12+(100-ROW())/1000,-1) -> 15.088 | AB12: =IF($T12="Yes",J12+(100-ROW())/1000,-1) -> 8.088 | AC12: =IF($T12="Yes",K12+(100-ROW())/1000,-1) -> 15.088 | AD12: =IF($T12="Yes",I12+(100-ROW())/1000,-1) -> 12.088 | AE12: =IF($T12="Yes",L12+(100-ROW())/1000,-1) -> 5.088 | AF12: =IF($T12="Yes",M12+(100-ROW())/1000,-1) -> 5.088 | AG12: =IF($T12="Yes",N12+(100-ROW())/1000,-1) -> 2.088 | AH12: =IF($T12="Yes",O12+(100-ROW())/1000,-1) -> 6.088
A13: EDGE70P | B13: Motorola Edge 70 Pro (REFERENCE – over budget) | C13: 12GB + 256GB | D13: 2026 | E13: MediaTek Dimensity 8500-Extreme | F13: 12 | G13: 42985 | H13: 23 | I13: 14 | J13: 13 | K13: 12 | L13: 8 | M13: 5 | N13: 3 | O13: 6 | P13: =SUM(H13:O13) -> 84 | Q13: =IF(G13<=40000,"Yes","No") -> No | R13: =IF(F13>=12,"Yes","No") -> Yes | S13: Yes | T13: =IF(AND(Q13="Yes",R13="Yes",S13="Yes"),"Yes","No") -> No | U13: =IF(T13="Yes",COUNTIFS($T$5:$T$13,"Yes",$P$5:$P$13,">"&P13)+1,"Excluded") -> Excluded | V13: =G13-$G$5 -> 5986 | W13: =HYPERLINK("https://www.91mobiles.com/motorola-edge-70-pro-5g-price-in-india","Open listing / source") -> Open listing / source | X13: Best all-rounder on paper (D8500-Extreme, AnTuTu ~2.17M, 50MP main + 50MP ultrawide, 50MP selfie, 5,200-nit, IP68/69 + MIL-STD, 3 OS + 5 yr). Excluded: regular price ₹42,985+. | Z13: =IF($T13="Yes",P13+(100-ROW())/1000,-1) -> -1 | AA13: =IF($T13="Yes",H13+(100-ROW())/1000,-1) -> -1 | AB13: =IF($T13="Yes",J13+(100-ROW())/1000,-1) -> -1 | AC13: =IF($T13="Yes",K13+(100-ROW())/1000,-1) -> -1 | AD13: =IF($T13="Yes",I13+(100-ROW())/1000,-1) -> -1 | AE13: =IF($T13="Yes",L13+(100-ROW())/1000,-1) -> -1 | AF13: =IF($T13="Yes",M13+(100-ROW())/1000,-1) -> -1 | AG13: =IF($T13="Yes",N13+(100-ROW())/1000,-1) -> -1 | AH13: =IF($T13="Yes",O13+(100-ROW())/1000,-1) -> -1
B14: Maximum points | H14: 25 | I14: 15 | J14: 15 | K14: 15 | L14: 10 | M14: 5 | N14: 5 | O14: 10 | P14: =SUM(H14:O14) -> 100
B16: CATEGORY WINNERS (eligible phones only – formula driven)
B17: Category | C17: Winning score | D17: Winner (first on ties) | E17: Variant | F17: Regular price (₹)
B18: Overall total | C18: =_xlfn.MAXIFS($P$5:$P$13,$T$5:$T$13,"Yes") -> 81 | D18: =INDEX($B$5:$B$13,MATCH(1,INDEX(($P$5:$P$13=C18)*($T$5:$T$13="Yes"),0),0)) -> realme GT 7T 5G | E18: =INDEX($C$5:$C$13,MATCH(D18,$B$5:$B$13,0)) -> 12GB + 256GB | F18: =INDEX($G$5:$G$13,MATCH(D18,$B$5:$B$13,0)) -> 37999
B19: Processor & sustained | C19: =_xlfn.MAXIFS($H$5:$H$13,$T$5:$T$13,"Yes") -> 24 | D19: =INDEX($B$5:$B$13,MATCH(1,INDEX(($H$5:$H$13=C19)*($T$5:$T$13="Yes"),0),0)) -> OPPO K13 Turbo Pro 5G | E19: =INDEX($C$5:$C$13,MATCH(D19,$B$5:$B$13,0)) -> 12GB + 256GB | F19: =INDEX($G$5:$G$13,MATCH(D19,$B$5:$B$13,0)) -> 33999
B20: Display | C20: =_xlfn.MAXIFS($I$5:$I$13,$T$5:$T$13,"Yes") -> 13 | D20: =INDEX($B$5:$B$13,MATCH(1,INDEX(($I$5:$I$13=C20)*($T$5:$T$13="Yes"),0),0)) -> realme GT 7T 5G | E20: =INDEX($C$5:$C$13,MATCH(D20,$B$5:$B$13,0)) -> 12GB + 256GB | F20: =INDEX($G$5:$G$13,MATCH(D20,$B$5:$B$13,0)) -> 37999
